Workbook

Sheet Overview
A1: Stasiun | B1: Pantai | C1: Lokasi | D1: Longtitude (X) | E1: Latitude (Y) | F1: Tutupan Lamun | G1: Tutupan Makroalga | H1: Tutupan Perifiton | I1: Hasil IKEL/SEQI | J1: Klasifikasi | K1: Aktivitas | L1: Nilai PTSI | M1: Nilai TSI | N1: Stok Karbon Lamun (tonC/ha) | O1: Stok Karbon Sedimen (tonC/ha) | P1: Salinitas | Q1: Suhu | R1: pH | S1: Nama Desa
A2: RMBG.SG01 | B2: Pulau Marongan | C2: Rembang | D2: 111.260958 | E2: -6.667458 | F2: 40.198864 | G2: 32.727273 | H2: 47.424242 | I2: 0.53120581 | J2: Sedang | K2: Wisata; Memancing | L2: 8 | M2: 16 | N2: 0.4 | O2: 48.810789 | P2: 31 | Q2: 32.2 | R2: 7.5 | S2: Desa Tasikharjo
A3: RMBG.SG02 | B3: Pantai Leran 1 (Barat) | C3: Rembang | D3: 111.468644 | E3: -6.637642 | F3: 32.054924 | G3: 19.924242 | H3: 34.090909 | I3: 0.54496843 | J3: Sedang | K3: Tambak; PLTU | L3: 4 | M3: 8 | N3: 0.37 | O3: 77.717691 | P3: 25 | Q3: 32 | R3: 7.3 | S3: Desa Leran
A4: RMBG.SG03 | B4: Pantai Leran 2 (Timur) | C4: Rembang | D4: 111.478622 | E4: -6627403 | F4: 34.280303 | G4: 16.477273 | H4: 34.848485 | I4: 0.55479798 | J4: Sedang | K4: Tambak; PLTU | L4: 8 | M4: 16 | N4: 0.33 | O4: 37.029539 | P4: 29 | Q4: 33.6 | R4: 7.4 | S4: Desa Trahan
A5: JPRA.SG01 | B5: Pantai Prawean | C5: Jepara | D5: 110.653732 | E5: -6.564077 | F5: 45.217803 | G5: 15.151515 | H5: 33.636364 | I5: 0.62619318 | J5: Sedang | K5: Wisata; Kapal | L5: 8 | M5: 16 | N5: 0.55 | O5: 78.381489 | P5: 33 | Q5: 33.7 | R5: 7.3 | S5: Desa Bandengan
A6: JPRA.SG02 | B6: Pantai Kayu Apung | C6: Jepara | D6: 110.654463 | E6: -6.549433 | F6: 42.755682 | G6: 10.606061 | H6: 52.878788 | I6: 0.591875 | J6: Sedang | K6: Akuakultur | L6: 8 | M6: 16 | N6: 0.53 | O6: 51.758469 | P6: 32 | Q6: 31.5 | R6: 7.1 | S6: Desa Bandengan
A7: JPRA.SG03 | B7: Pulau Panjang | C7: Jepara | D7: 110.630877 | E7: -6.576186 | F7: 67.850379 | G7: 11.212121 | H7: 19.545455 | I7: 0.80751894 | J7: Baik | K7: Wisata; Kapal | L7: 16 | M7: 16 | N7: 0.57 | O7: 63.198597 | P7: 35 | Q7: 46051 | R7: 46180 | S7: Desa Ujung Batu
A8: JPRA.SG04 | B8: Pantai Ujung Piring | C8: Jepara | D8: 110.669646 | E8: -6.511672 | F8: 16.077652 | G8: 12.307692 | H8: 7.7272727 | I8: 0.55875204 | J8: Sedang | K8: Wisata; Memancing; Dermaga; Memancing | L8: 4 | M8: 8 | N8: 0.3 | O8: 28.389033 | P8: 30 | Q8: 31.2 | R8: 7.2 | S8: Desa Jambu
A9: JPRA.SG05 | B9: Pantai Blebak | C9: Jepara | D9: 110.67042 | E9: -6.50291 | F9: 20.746212 | G9: 4.8076923 | H9: 17.878788 | I9: 0.66278613 | J9: Sedang | K9: Wisata; Memancing | L9: 16 | M9: 16 | N9: 0.31 | O9: 31.491949 | P9: 33 | Q9: 31.5 | R9: 7.5 | S9: Desa Jambu
A10: JPRA.SG06 | B10: Pantai Kartini | C10: Jepara | D10: 110.65236 | E10: -6.56408 | F10: 11.079545 | G10: 6.9230769 | H10: 20.30303 | I10: 0.51215132 | J10: Buruk | K10: Wisata; Kapal | L10: n/a | M10: n/a | N10: 0.29 | O10: 27.619565 | P10: 34 | Q10: 30.8 | R10: 7.4 | S10: Desa Bulu
A11: JPRA.SG07 | B11: Pantai Semat | C11: Jepara | D11: 110.63885 | E11: -6.63733 | F11: 36.505682 | G11: 30.384615 | H11: 52.272727 | I11: 0.49658557 | J11: Buruk | K11: Wisata; Gleaning | L11: 4 | M11: 8 | N11: 0.38 | O11: 69.287587 | P11: 32 | Q11: 31.3 | R11: 7.5 | S11: Desa Semat
A12: JPRA.SG08 | B12: Pantai Teluk Awur | C12: Jepara | D12: 110.63732 | E12: -6.62193 | F12: 29.356061 | G12: 14.038462 | H12: 19.545455 | I12: 0.6026554 | J12: Sedang | K12: Tambak; Gleaning | L12: 8 | M12: 16 | N12: 0.36 | O12: 38.876839 | P12: 32 | Q12: 32.6 | R12: 7.5 | S12: Desa Teluk Awur
A13: JPRA.SG09 | B13: Pantai Salor | C13: Jepara | D13: 110.668667 | E13: -6.533211 | F13: 19.318182 | G13: 18.846154 | H13: 23.939394 | I13: 0.5863986 | J13: Sedang | K13: Wisata | L13: 8 | M13: 16 | N13: 0.31 | O13: 29.212126 | P13: 34 | Q13: 33.1 | R13: 7.1 | S13: Desa Mororejo
B14: Pantai Marina | C14: Jepara | D14: 110.655078 | E14: -6.565669 | F14: n/a | G14: n/a | H14: n/a | I14: n/a | J14: n/a | K14: Wisata; Dermaga | L14: 4 | M14: 8 | N14: n/a | O14: n/a | P14: 33 | Q14: 32.8 | R14: 7.2 | S14: Desa Bandengan
A15: CLCP.SG01 | B15: Pantai Tebeng 1 | C15: Cilacap | D15: 109.035878 | E15: -7.763661 | F15: 35.814394 | G15: 13.939394 | H15: 28.939394 | I15: 0.65253788 | J15: Sedang | K15: Wisata; Memancing | L15: 8 | M15: 16 | N15: 0.42 | O15: 38.254529 | P15: 34 | Q15: 30.8 | R15: 7.4 | S15: Desa Tambakreja
A16: CLCP.SG02 | B16: Pantai Tebeng 2 | C16: Cilacap | D16: 109.034642 | E16: -7.765253 | F16: 36.458333 | G16: 17.878788 | H16: 32.727273 | I16: 0.59392677 | J16: Sedang | K16: Wisata; Memancing | L16: 8 | M16: 16 | N16: n/a | O16: n/a | P16: 34 | Q16: 31.3 | R16: 7.6 | S16: Desa Tambakreja
A17: CLCP.SG03 | B17: Pantai Karang Tengah | C17: Cilacap | D17: 109.028900 | E17: -7.765328 | F17: 36.214015 | G17: 23.333333 | H17: 40.30303 | I17: 0.53404419 | J17: Sedang | K17: Wisata; Memancing, Jetty | L17: 4 | M17: 8 | N17: 0.41 | O17: 37.692169 | P17: 35 | Q17: 32.2 | R17: 7.5 | S17: Desa Tambakreja

Sheet PTSI dan TSI
A1: PTSI / TSI | G1: KABUPATEN JEPARA | U1: KABUPATEN REMBANG | X1: KABUPATEN CILACAP
G2: No | H2: Parameter PTSI | I2: Pulau Panjang (Timur) | J2: Pulau Panjang (Barat) | K2: Pantai Prawean (1) | L2: Pantai Prawean (2) | M2: Pantai Blebak | N2: Pantai Ujung Piring | O2: Pantai Kayu Apung | P2: Pantai Marina | Q2: Pantai Semat | R2: Pantai Teluk Awur (1) | S2: Pantai Teluk Awur (2) | T2: Pantai Salor | U2: Pulau Marongan | V2: Pantai Leran (Barat PLTU) | W2: Pantai Leran (Timur PLTU) | X2: Pantai Tebeng (1) | Y2: Pantai Tebeng (2) | Z2: Pantai Karang Tengah
A3: No | B3: Parameter PTSI | C3: Penilaian PTSI | G3: Titik Koordinat | I3: 6°34'31.76"S 110°37'51.73"E | J3: 6°34'36.59"S 110°37'37.03"E | K3: 6°33'50.15"S 110°39'11.75"E | L3: 6°33'39.55"S 110°38'59.73"E | M3: 6°30'09.54"S 110°40'11.80"E | N3: 6°30'41.34"S 110°40'10.07"E | O3: 6°33'00.36"S 110°39'14.26"E | P3: 6°33'56.41"S 110°39'18.28"E | Q3: 6°38'13.19"S 110°38'20.70"E | R3: 6°37'33.39"S 110°38'12.44"E | S3: 6°37'00.26"S 110°38'22.66"E | T3: 6°32'03.80"S 110°40'09.12"E | U3: 6°40'00.28"S 111°15'40.22"E | V3: 6°38'16.27"S 111°28'08.20"E | W3: 6°37'39.54"S 111°28'44.33"E | X3: 7°45'49.18"S 109°02'09.16"E | Y3: 7°45'54.91"S 109°02'04.71"E | Z3: 7°45'55.18"S 109°01'44.04"E
A4: 1 | B4: Distribusi lamun historis | C4: (1) Untuk area yang sebelumnya tidak bervegetasi (2) Untuk area yang sebelumnya bervegetasi | G4: 1 | H4: Distribusi lamun historis | I4: 2 | J4: 1 | K4: 2 | L4: 2 | M4: 2 | N4: 2 | O4: 2 | P4: 2 | Q4: 2 | R4: 2 | S4: 2 | T4: 2 | U4: 2 | V4: 2 | W4: 2 | X4: 2 | Y4: 2 | Z4: 2
A5: 2 | B5: Distribusi lamun saat ini | C5: (0) Untuk area yang saat ini bervegetasi (1) Untuk area yang saat ini tidak bervegetasi | G5: 2 | H5: Distribusi lamun saat ini | I5: 1 | J5: 1 | K5: 1 | L5: 1 | M5: 1 | N5: 1 | O5: 1 | P5: 1 | Q5: 1 | R5: 1 | S5: 1 | T5: 1 | U5: 1 | V5: 1 | W5: 1 | X5: 1 | Y5: 1 | Z5: 1
A6: 3 | B6: Kedekatan dengan padang lamun alami | C6: (0) Untuk < 100 m (1) Untuk ≥ 100 m | G6: 3 | H6: Kedekatan dengan padang lamun alami | I6: 1 | J6: 1 | K6: 1 | L6: 1 | M6: 1 | N6: 1 | O6: 1 | P6: 1 | Q6: 1 | R6: 1 | S6: 1 | T6: 1 | U6: 1 | V6: 1 | W6: 1 | X6: 1 | Y6: 1 | Z6: 1
A7: 4 | B7: Sedimen | C7: (0) Untuk batuan atau kerikil (1) Untuk > 70% lumpur/tanah liat (2) Untuk kerikil bebas dengan <70% lumpur/tanah liat | G7: 4 | H7: Sedimen | I7: 2 | J7: 2 | K7: 2 | L7: 2 | M7: 1 | N7: 1 | O7: 2 | P7: 1 | Q7: 1 | R7: 2 | S7: 2 | T7: 2 | U7: 2 | V7: 1 | W7: 2 | X7: 2 | Y7: 2 | Z7: 1
A8: 5 | B8: Paparan Gelombang | C8: (0) Untuk > rata-rata + 2 SD hasil pengukuran relatif terhadap indeks paparan di setiap lokasi (1) Untuk ≤ rata-rata + 2 SD hasil pengukuran relatif terhadap indeks paparan di setiap lokasi | G8: 5 | H8: Paparan Gelombang | I8: 1 | J8: 1 | K8: 1 | L8: 1 | M8: 1 | N8: 1 | O8: 1 | P8: 1 | Q8: 1 | R8: 1 | S8: 1 | T8: 1 | U8: 1 | V8: 1 | W8: 1 | X8: 1 | Y8: 1 | Z8: 1
A9: 6 | B9: Kedalaman air | C9: (0) Untuk > 2 m saat air surut (1) Untuk < 0,5 m atau 1,5 - 2 m saat air surut (2) Untuk 0,5 - 1,5 m saat air surut | G9: 6 | H9: Kedalaman air | I9: 2 | J9: 2 | K9: 2 | L9: 2 | M9: 2 | N9: 2 | O9: 2 | P9: 2 | Q9: 2 | R9: 2 | S9: 2 | T9: 2 | U9: 2 | V9: 2 | W9: 2 | X9: 2 | Y9: 2 | Z9: 2
A10: 7 | B10: Kualitas air (TSS) | C10: (1) Untuk > 20 mg/L (2) Untuk < 20 mg/L | G10: 7 | H10: Kualitas air (TSS) | I10: 2 | J10: 2 | K10: 1 | L10: 1 | M10: 2 | N10: 1 | O10: 1 | P10: 1 | Q10: 1 | R10: 1 | S10: 1 | T10: 1 | U10: 1 | V10: 1 | W10: 1 | X10: 1 | Y10: 1 | Z10: 1
A11: TOTAL SKOR PTSI | C11: Nilai yang akan muncul 0, 1, 2, 4, 8, dan 16 | G11: TOTAL SKOR PTSI | I11: =I4*I5*I6*I7*I8*I9*I10 -> 16 | J11: =J4*J5*J6*J7*J8*J9*J10 -> 8 | K11: =K4*K5*K6*K7*K8*K9*K10 -> 8 | L11: =L4*L5*L6*L7*L8*L9*L10 -> 8 | M11: =M4*M5*M6*M7*M8*M9*M10 -> 8 | N11: =N4*N5*N6*N7*N8*N9*N10 -> 4 | O11: =O4*O5*O6*O7*O8*O9*O10 -> 8 | P11: =P4*P5*P6*P7*P8*P9*P10 -> 4 | ... Z11: =Z4*Z5*Z6*Z7*Z8*Z9*Z10 -> 4
A12: No | B12: Parameter TSI | C12: Penilaian TSI | G12: No | H12: Parameter TSI | I12: Pulau Panjang (Timur) | J12: Pulau Panjang (Barat) | K12: Pantai Prawean (1) | L12: Pantai Prawean (2) | M12: Pantai Blebak | N12: Pantai Ujung Piring | O12: Pantai Kayu Apung | P12: Pantai Marina | Q12: Pantai Semat | R12: Pantai Teluk Awur (1) | S12: Pantai Teluk Awur (2) | T12: Pantai Salor | U12: Pulau Marongan | V12: Pantai Leran (Barat PLTU) | W12: Pantai Leran (Timur PLTU) | X12: Pantai Tebeng (1) | Y12: Pantai Tebeng (2) | Z12: Pantai Karang Tengah
A13: 1 | B13: PTSI | C13: (0) Untuk PTSI = 0 - 1 (1) Untuk PTSI = 2 - 4 (2) Untuk PTSI = 8 -16 | G13: 1 | H13: PTSI | I13: 2 | J13: 2 | K13: 2 | L13: 2 | M13: 2 | N13: 1 | O13: 2 | P13: 1 | Q13: 1 | R13: 2 | S13: 2 | T13: 2 | U13: 2 | V13: 1 | W13: 2 | X13: 2 | Y13: 2 | Z13: 1
A14: 2 | B14: Cahaya (data lapangan) | C14: (0) Untuk < 20% intensitas permukaan (1) Untuk ≥ 20% intensitas permukaan (2) Untuk intensitas > lamun referensi | G14: 2 | H14: Cahaya (data lapangan) | I14: 2 | J14: 2 | K14: 2 | L14: 2 | M14: 2 | N14: 2 | O14: 2 | P14: 2 | Q14: 2 | R14: 2 | S14: 2 | T14: 2 | U14: 2 | V14: 2 | W14: 2 | X14: 2 | Y14: 2 | Z14: 2
A15: 3 | B15: Bioturbasi (data lapangan) | C15: (0) Untuk melimpah (1) Untuk ada (2) Untuk tidak ada | G15: 3 | H15: Bioturbasi (data lapangan) | I15: 2 | J15: 2 | K15: 2 | L15: 2 | M15: 2 | N15: 2 | O15: 2 | P15: 2 | Q15: 2 | R15: 2 | S15: 2 | T15: 2 | U15: 2 | V15: 2 | W15: 2 | X15: 2 | Y15: 2 | Z15: 2
A16: 4 | B16: Kelangsungan hidup lamun (uji transplantasi) | C16: (0) Untuk < 20% (1) Untuk 20 - 40% (2) Untuk > 40% | G16: 4 | H16: Kelangsungan hidup lamun (uji transplantasi) | I16: 2 | J16: 2 | K16: 2 | L16: 2 | M16: 2 | N16: 2 | O16: 2 | P16: 2 | Q16: 2 | R16: 2 | S16: 2 | T16: 2 | U16: 2 | V16: 2 | W16: 2 | X16: 2 | Y16: 2 | Z16: 2
A17: TOTAL SKOR TSI | C17: Nilai yang akan muncul 0, 1, 2, 4, 8, dan 16 | G17: TOTAL SKOR TSI | I17: =I13*I14*I15*I16 -> 16 | J17: =J13*J14*J15*J16 -> 16 | K17: =K13*K14*K15*K16 -> 16 | L17: =L13*L14*L15*L16 -> 16 | M17: =M13*M14*M15*M16 -> 16 | N17: =N13*N14*N15*N16 -> 8 | O17: =O13*O14*O15*O16 -> 16 | P17: =P13*P14*P15*P16 -> 8 | ... Z17: =Z13*Z14*Z15*Z16 -> 8
G20: KABUPATEN JEPARA | U20: KABUPATEN REMBANG | X20: KABUPATEN CILACAP
G21: No | H21: Parameter PTSI | I21: Pulau Panjang (Timur) | J21: Pulau Panjang (Barat) | K21: Pantai Prawean (1) | L21: Pantai Prawean (2) | M21: Pantai Blebak | N21: Pantai Ujung Piring | O21: Pantai Kayu Apung | P21: Pantai Marina | Q21: Pantai Semat | R21: Pantai Teluk Awur (1) | S21: Pantai Teluk Awur (2) | T21: Pantai Salor | U21: Pulau Marongan | V21: Pantai Leran (Barat PLTU) | W21: Pantai Leran (Timur PLTU) | X21: Pantai Tebeng (1) | Y21: Pantai Tebeng (2) | Z21: Pantai Karang Tengah
G22: Titik Koordinat | I22: 6°34'31.76"S 110°37'51.73"E | J22: 6°34'36.59"S 110°37'37.03"E | K22: 6°33'50.15"S 110°39'11.75"E | L22: 6°33'39.55"S 110°38'59.73"E | M22: 6°30'09.54"S 110°40'11.80"E | N22: 6°30'41.34"S 110°40'10.07"E | O22: 6°33'00.36"S 110°39'14.26"E | P22: 6°33'56.41"S 110°39'18.28"E | Q22: 6°38'13.19"S 110°38'20.70"E | R22: 6°37'33.39"S 110°38'12.44"E | S22: 6°37'00.26"S 110°38'22.66"E | T22: 6°32'03.80"S 110°40'09.12"E | U22: 6°40'00.28"S 111°15'40.22"E | V22: 6°38'16.27"S 111°28'08.20"E | W22: 6°37'39.54"S 111°28'44.33"E | X22: 7°45'49.18"S 109°02'09.16"E | Y22: 7°45'54.91"S 109°02'04.71"E | Z22: 7°45'55.18"S 109°01'44.04"E
G23: 1 | H23: Distribusi lamun historis | I23: Sebelumnya bervegetasi | J23: Sebelumnya tidak bervegetasi | K23: Sebelumnya bervegetasi | L23: Sebelumnya bervegetasi | M23: Sebelumnya bervegetasi | N23: Sebelumnya bervegetasi | O23: Sebelumnya bervegetasi | P23: Sebelumnya bervegetasi | Q23: Sebelumnya bervegetasi | R23: Sebelumnya bervegetasi | S23: Sebelumnya bervegetasi | T23: Sebelumnya bervegetasi | U23: Sebelumnya bervegetasi | V23: Sebelumnya bervegetasi | W23: Sebelumnya bervegetasi | X23: Sebelumnya bervegetasi | Y23: Sebelumnya bervegetasi | Z23: Sebelumnya bervegetasi
G24: 2 | H24: Distribusi lamun saat ini | I24: Tidak bervegetasi | J24: Tidak bervegetasi | K24: Tidak bervegetasi | L24: Tidak bervegetasi | M24: Tidak bervegetasi | N24: Tidak bervegetasi | O24: Tidak bervegetasi | P24: Tidak bervegetasi | Q24: Tidak bervegetasi | R24: Tidak bervegetasi | S24: Tidak bervegetasi | T24: Tidak bervegetasi | U24: Tidak bervegetasi | V24: Tidak bervegetasi | W24: Tidak bervegetasi | X24: Tidak bervegetasi | Y24: Tidak bervegetasi | Z24: Tidak bervegetasi
G25: 3 | H25: Kedekatan dengan padang lamun alami | I25: ≥ 100 m | J25: ≥ 100 m | K25: ≥ 100 m | L25: ≥ 100 m | M25: ≥ 100 m | N25: ≥ 100 m | O25: ≥ 100 m | P25: ≥ 100 m | Q25: ≥ 100 m | R25: ≥ 100 m | S25: ≥ 100 m | T25: ≥ 100 m | U25: ≥ 100 m | V25: ≥ 100 m | W25: ≥ 100 m | X25: ≥ 100 m | Y25: ≥ 100 m | Z25: ≥ 100 m
G26: 4 | H26: Sedimen | I26: Pasir | J26: Pasir | K26: Lumpur | L26: Lumpur | M26: Pasir | N26: Lumpur | O26: Pasir | P26: Pasir | Q26: Lumpur | R26: Pasir | S26: Pasir | T26: Pasir | U26: Pasir | V26: Lumpur | W26: Pasir | X26: Pasir | Y26: Pasir | Z26: Lumpur
G27: 5 | H27: Paparan Gelombang | I27: dibawah rata-rata | J27: dibawah rata-rata | K27: dibawah rata-rata | L27: dibawah rata-rata | M27: dibawah rata-rata | N27: dibawah rata-rata | O27: dibawah rata-rata | P27: dibawah rata-rata | Q27: dibawah rata-rata | R27: dibawah rata-rata | S27: dibawah rata-rata | T27: dibawah rata-rata | U27: dibawah rata-rata | V27: dibawah rata-rata | W27: dibawah rata-rata | X27: dibawah rata-rata | Y27: dibawah rata-rata | Z27: dibawah rata-rata
G28: 6 | H28: Kedalaman air | I28: 0,5 - 1,5 m | J28: 0,5 - 1,5 m | K28: 0,5 - 1,5 m | L28: 0,5 - 1,5 m | M28: 0,5 - 1,5 m | N28: 0,5 - 1,5 m | O28: 0,5 - 1,5 m | P28: 0,5 - 1,5 m | Q28: 0,5 - 1,5 m | R28: 0,5 - 1,5 m | S28: 0,5 - 1,5 m | T28: 0,5 - 1,5 m | U28: 0,5 - 1,5 m | V28: 0,5 - 1,5 m | W28: 0,5 - 1,5 m | X28: 0,5 - 1,5 m | Y28: 0,5 - 1,5 m | Z28: 0,5 - 1,5 m
G29: 7 | H29: Kualitas air (TSS) | I29: < 20 mg/L | J29: < 20 mg/L | K29: > 20 mg/L | L29: > 20 mg/L | M29: < 20 mg/L | N29: > 20 mg/L | O29: > 20 mg/L | P29: > 20 mg/L | Q29: > 20 mg/L | R29: > 20 mg/L | S29: > 20 mg/L | T29: > 20 mg/L | U29: > 20 mg/L | V29: > 20 mg/L | W29: > 20 mg/L | X29: > 20 mg/L | Y29: > 20 mg/L | Z29: > 20 mg/L
G30: TOTAL SKOR PTSI | I30: =I11 -> 16 | J30: =J11 -> 8 | K30: =K11 -> 8 | L30: =L11 -> 8 | M30: =M11 -> 8 | N30: =N11 -> 4 | O30: =O11 -> 8 | P30: =P11 -> 4 | ... Z30: =Z11 -> 4
G31: No | H31: Parameter TSI | I31: Pulau Panjang (Timur) | J31: Pulau Panjang (Barat) | K31: Pantai Prawean (1) | L31: Pantai Prawean (2) | M31: Pantai Blebak | N31: Pantai Ujung Piring | O31: Pantai Kayu Apung | P31: Pantai Marina | Q31: Pantai Semat | R31: Pantai Teluk Awur (1) | S31: Pantai Teluk Awur (2) | T31: Pantai Salor | U31: Pulau Marongan | V31: Pantai Leran (Barat PLTU) | W31: Pantai Leran (Timur PLTU) | X31: Pantai Tebeng (1) | Y31: Pantai Tebeng (2) | Z31: Pantai Karang Tengah
G32: 1 | H32: PTSI | I32: 8 | J32: 8 | K32: 8 | L32: 8 | M32: 8 | N32: 4 | O32: 8 | P32: 4 | Q32: 4 | R32: 8 | S32: 8 | T32: 8 | U32: 8 | V32: 4 | W32: 8 | X32: 8 | Y32: 8 | Z32: 4
G33: 2 | H33: Cahaya (data lapangan) | I33: ≥ lamun referensi | J33: ≥ lamun referensi | K33: ≥ lamun referensi | L33: ≥ lamun referensi | M33: ≥ lamun referensi | N33: ≥ lamun referensi | O33: ≥ lamun referensi | P33: ≥ lamun referensi | Q33: ≥ lamun referensi | R33: ≥ lamun referensi | S33: ≥ lamun referensi | T33: ≥ lamun referensi | U33: ≥ lamun referensi | V33: ≥ lamun referensi | W33: ≥ lamun referensi | X33: ≥ lamun referensi | Y33: ≥ lamun referensi | Z33: ≥ lamun referensi
G34: 3 | H34: Bioturbasi (data lapangan) | I34: Tidak ada | J34: Tidak ada | K34: Tidak ada | L34: Tidak ada | M34: Tidak ada | N34: Tidak ada | O34: Tidak ada | P34: Tidak ada | Q34: Tidak ada | R34: Tidak ada | S34: Tidak ada | T34: Tidak ada | U34: Tidak ada | V34: Tidak ada | W34: Tidak ada | X34: Tidak ada | Y34: Tidak ada | Z34: Tidak ada
G35: 4 | H35: Kelangsungan hidup lamun (uji transplantasi) | I35: 0.675 | J35: 0.6 | K35: 0.6 | L35: 0.65 | M35: 0.7 | N35: 0.65 | O35: 0.63 | P35: 0.6 | Q35: 0.6 | R35: 0.65 | S35: 0.63 | T35: 0.6 | U35: 0.65 | V35: 0.6 | W35: 0.63 | X35: 0.7 | Y35: 0.68 | Z35: 0.63
G36: TOTAL SKOR TSI | I36: =I17 -> 16 | J36: =J17 -> 16 | K36: =K17 -> 16 | L36: =L17 -> 16 | M36: =M17 -> 16 | N36: =N17 -> 8 | O36: =O17 -> 16 | P36: =P17 -> 8 | ... Z36: =Z17 -> 8
G57: KABUPATEN CILACAP
G58: No | H58: Parameter PTSI | I58: Pantai Tebeng 1 | J58: Pantai Tebeng 2 | K58: Pantai Karang Tengah
G59: Titik Koordinat | I59: 7°45'49.18"S 109°02'09.16"E | J59: 7°45'54.91"S 109°02'04.71"E | K59: 7°45'55.18"S 109°01'44.04"E
G60: 1 | H60: Distribusi lamun historis | I60: Sebelumnya bervegetasi | J60: Sebelumnya bervegetasi | K60: Sebelumnya bervegetasi
G61: 2 | H61: Distribusi lamun saat ini | I61: Tidak bervegetasi | J61: Tidak bervegetasi | K61: Tidak bervegetasi
G62: 3 | H62: Kedekatan dengan padang lamun alami | I62: ≥ 100 m | J62: ≥ 100 m | K62: ≥ 100 m
...

Sheet Analisis Data
A1: No | B1: Lokasi/Pulau | C1: Stasiun | D1: Rata-Rata Penutupan Lamun (%) | E1: STD EROR | F1: Dominansi Jenis (%) | N1: Nilai Parameter Pendukung (Rata-rata) | P1: Kecerahan Perairan | Q1: Jumlah Spesies | R1: IKEL/SEQI | S1: Status IKEL | U1: Status IKEL:
F2: Ea | G2: Th | H2: Cr | I2: Os | J2: Hu | K2: Si | L2: Hp | M2: Ho | N2: Tutupan Makroalga (%) | O2: Tutupan Perifiton (%) | U2: 0 <= n <= 0.36 | V2: : Sangat Buruk
A3: 1 | B3: Pulau Marongan | C3: RMBG.SG01 | D3: ='Rembang - Pulau Marongan'!J44 -> 40.198864 | E3: =D3/sqrt(Q3) -> 17.977478 | F3: ='Rembang - Pulau Marongan'!O44 -> 6.2026515 | G3: ='Rembang - Pulau Marongan'!T44 -> 13.967803 | H3: ='Rembang - Pulau Marongan'!Y44 -> 5.4450758 | I3: ='Rembang - Pulau Marongan'!AI44 -> 11.789773 | M3: ='Rembang - Pulau Marongan'!AD44 -> 2.7935606 | N3: ='Rembang - Pulau Marongan'!AL44 -> 32.727273 | O3: ='Rembang - Pulau Marongan'!AM44 -> 47.424242 | P3: 1 | Q3: =Count(F3:M3) -> 5 | R3: =(Q3/9)*0.2+(D3/100)*0.2+(P3/2)*0.2+(1-(N3/100))*0.2+(1-(O3/100))*0.2 -> 0.53120581 | S3: Sedang | U3: 0.37 <= n <= 0.52 | V3: : Buruk
A4: 2 | B4: Pantai Leran 1 (Barat) | C4: RMBG.SG02 | D4: ='Rembang - Pantai Leran 1 (Barat'!J44 -> 32.054924 | E4: =D4/sqrt(Q4) -> 16.027462 | F4: ='Rembang - Pantai Leran 1 (Barat'!O44 -> 5.5397727 | G4: ='Rembang - Pantai Leran 1 (Barat'!T44 -> 12.594697 | H4: ='Rembang - Pantai Leran 1 (Barat'!Y44 -> 4.782197 | I4: ='Rembang - Pantai Leran 1 (Barat'!AD44 -> 9.1382576 | N4: ='Rembang - Pantai Leran 1 (Barat'!AG44 -> 19.924242 | O4: ='Rembang - Pantai Leran 1 (Barat'!AH44 -> 34.090909 | P4: 1 | Q4: =Count(F4:M4) -> 4 | R4: =(Q4/9)*0.2+(D4/100)*0.2+(P4/2)*0.2+(1-(N4/100))*0.2+(1-(O4/100))*0.2 -> 0.54496843 | S4: Sedang | U4: 0.53 <= n <= 0.68 | V4: : Sedang
A5: 3 | B5: Pantai Leran 2 (Timur) | C5: RMBG.SG03 | D5: ='Rembang - Pantai Leran 2 (Timur'!J44 -> 34.280303 | E5: =D5/sqrt(Q5) -> 17.140152 | F5: ='Rembang - Pantai Leran 2 (Timur'!O44 -> 1.7992424 | G5: ='Rembang - Pantai Leran 2 (Timur'!T44 -> 10.653409 | H5: ='Rembang - Pantai Leran 2 (Timur'!Y44 -> 2.5568182 | I5: ='Rembang - Pantai Leran 2 (Timur'!AD44 -> 19.270833 | N5: ='Rembang - Pantai Leran 2 (Timur'!AG44 -> 16.477273 | O5: ='Rembang - Pantai Leran 2 (Timur'!AH44 -> 34.848485 | P5: 1 | Q5: =Count(F5:M5) -> 4 | R5: =(Q5/9)*0.2+(D5/100)*0.2+(P5/2)*0.2+(1-(N5/100))*0.2+(1-(O5/100))*0.2 -> 0.55479798 | S5: Sedang | U5: 0.69 <= n <= 0.84 | V5: : Baik
C6: Rata - Rata | D6: =AVERAGE(D3:D5) -> 35.511364 | F6: =AVERAGE(F3:F5) -> 4.5138889 | G6: =AVERAGE(G3:G5) -> 12.405303 | H6: =AVERAGE(H3:H5) -> 4.2613636 | I6: =AVERAGE(I3:I5) -> 13.399621 | M6: =AVERAGE(M3:M5) -> 2.7935606 | N6: =AVERAGE(N3:N5) -> 23.042929 | O6: =AVERAGE(O3:O5) -> 38.787879 | R6: =AVERAGE(R3:R5) -> 0.54365741 | S6: Sedang | U6: 0.85 <= n <= 1 | V6: : Sangat Baik
C7: STDEV | D7: =STDEV(D3:D5) -> 4.2092244
A11: No | B11: Lokasi/Pulau | C11: Stasiun | D11: Rata-Rata Penutupan Lamun (%) | E11: STD EROR | F11: Dominansi Jenis (%) | N11: Nilai Parameter Pendukung (Rata-rata) | P11: Kecerahan Perairan | Q11: Jumlah Spesies | R11: IKEL/SEQI | S11: Status IKEL
F12: Ea | G12: Th | H12: Cr | I12: Os | J12: Hu | K12: Si | L12: Hp | M12: Ho | N12: Tutupan Makroalga (%) | O12: Tutupan Perifiton (%)
A13: 1 | B13: Pantai Prawean | C13: JPRA.SG01 | D13: ='Jepara - Prawean'!J44 -> 45.217803 | E13: =D13/sqrt(Q13) -> 18.460091 | F13: ='Jepara - Prawean'!O44 -> 0.89962121 | G13: ='Jepara - Prawean'!T44 -> 10.700758 | H13: ='Jepara - Prawean'!Y44 -> 4.8295455 | I13: ='Jepara - Prawean'!AN44 -> 22.537879 | J13: ='Jepara - Prawean'!AI44 -> 4.7348485 | M13: ='Jepara - Prawean'!AD44 -> 1.5151515 | N13: ='Jepara - Prawean'!AQ44 -> 15.151515 | O13: ='Jepara - Prawean'!AR44 -> 33.636364 | P13: 1 | Q13: =Count(F13:M13) -> 6 | R13: =(Q13/9)*0.2+(D13/100)*0.2+(P13/2)*0.2+(1-(N13/100))*0.2+(1-(O13/100))*0.2 -> 0.62619318 | S13: Sedang
A14: 2 | B14: Pantai Kayu Apung | C14: JPRA.SG02 | D14: ='Jepara - Kayu Apung'!J44 -> 42.755682 | E14: =D14/sqrt(Q14) -> 17.454934 | F14: ='Jepara - Kayu Apung'!O44 -> 1.0890152 | G14: ='Jepara - Kayu Apung'!T44 -> 18.986742 | H14: ='Jepara - Kayu Apung'!Y44 -> 4.2613636 | I14: ='Jepara - Kayu Apung'!AN44 -> 16.761364 | J14: ='Jepara - Kayu Apung'!AI44 -> 0.9469697 | K14: ='Jepara - Kayu Apung'!AD44 -> 0.71022727 | N14: ='Jepara - Kayu Apung'!AQ44 -> 10.606061 | O14: ='Jepara - Kayu Apung'!AR44 -> 52.878788 | P14: 1 | Q14: =Count(F14:M14) -> 6 | R14: =(Q14/9)*0.2+(D14/100)*0.2+(P14/2)*0.2+(1-(N14/100))*0.2+(1-(O14/100))*0.2 -> 0.591875 | S14: Sedang
A15: 3 | B15: Pulau Panjang | C15: JPRA.SG03 | D15: ='Jepara - Pulau Panjang'!J44 -> 67.850379 | E15: =D15/sqrt(Q15) -> 27.699801 | F15: ='Jepara - Pulau Panjang'!O44 -> 1.657197 | G15: ='Jepara - Pulau Panjang'!T44 -> 17.518939 | H15: ='Jepara - Pulau Panjang'!Y44 -> 7.3863636 | I15: ='Jepara - Pulau Panjang'!AN44 -> 38.257576 | J15: ='Jepara - Pulau Panjang'!AI44 -> 1.4204545 | M15: ='Jepara - Pulau Panjang'!AD44 -> 1.6098485 | N15: ='Jepara - Pulau Panjang'!AQ44 -> 11.212121 | O15: ='Jepara - Pulau Panjang'!AR44 -> 19.545455 | P15: 2 | Q15: =Count(F15:M15) -> 6 | R15: =(Q15/9)*0.2+(D15/100)*0.2+(P15/2)*0.2+(1-(N15/100))*0.2+(1-(O15/100))*0.2 -> 0.80751894 | S15: Baik
A16: 4 | B16: Pantai Ujung Piring | C16: JPRA.SG04 | D16: ='Jepara - Ujung Piring'!J44 -> 16.077652 | E16: =D16/sqrt(Q16) -> 9.2824364 | F16: ='Jepara - Ujung Piring'!O44 -> 1.8465909 | G16: ='Jepara - Ujung Piring'!T44 -> 10.443182 | H16: ='Jepara - Ujung Piring'!Y44 -> 4.3560606 | I16: ='Rembang - Pantai Leran 1 (Barat'!AD56 | N16: ='Jepara - Ujung Piring'!AB44 -> 12.307692 | O16: ='Jepara - Ujung Piring'!AC44 -> 7.7272727 | P16: 1 | Q16: =Count(F16:M16) -> 3 | R16: =(Q16/9)*0.2+(D16/100)*0.2+(P16/2)*0.2+(1-(N16/100))*0.2+(1-(O16/100))*0.2 -> 0.55875204 | S16: Sedang
A17: 5 | B17: Pantai Blebak | C17: JPRA.SG05 | D17: ='Jepara - Blebak'!J44 -> 20.746212 | E17: =D17/sqrt(Q17) -> 11.977831 | G17: ='Jepara - Blebak'!T44 -> 9.3825758 | H17: ='Jepara - Blebak'!AD44 -> 9.6590909 | I17: ='Jepara - Blebak'!Y44 -> 1.7045455 | N17: ='Jepara - Blebak'!AG44 -> 4.8076923 | O17: ='Jepara - Blebak'!AH44 -> 17.878788 | P17: 2 | Q17: =Count(F17:M17) -> 3 | R17: =(Q17/9)*0.2+(D17/100)*0.2+(P17/2)*0.2+(1-(N17/100))*0.2+(1-(O17/100))*0.2 -> 0.66278613 | S17: Sedang
A18: 6 | B18: Pantai Kartini | C18: JPRA.SG06 | D18: ='Jepara - Kartini'!J44 -> 11.079545 | E18: =D18/sqrt(Q18) -> 7.8344217 | F18: ='Jepara - Kartini'!O44 -> 1.9886364 | G18: ='Jepara - Kartini'!T44 -> 9.0909091 | H18: ='Rembang - Pantai Leran 1 (Barat'!Y58 | I18: ='Rembang - Pantai Leran 1 (Barat'!AD58 | N18: ='Jepara - Kartini'!AG44 -> 6.9230769 | O18: ='Jepara - Kartini'!AH44 -> 20.30303 | P18: 1 | Q18: =Count(F18:M18) -> 2 | R18: =(Q18/9)*0.2+(D18/100)*0.2+(P18/2)*0.2+(1-(N18/100))*0.2+(1-(O18/100))*0.2 -> 0.51215132 | S18: Buruk
A19: 7 | B19: Pantai Semat | C19: JPRA.SG07 | D19: ='Jepara - Semat'!J44 -> 36.505682 | E19: =D19/sqrt(Q19) -> 18.252841 | F19: ='Jepara - Semat'!O44 -> 3.5037879 | G19: ='Jepara - Semat'!T44 -> 21.685606 | H19: ='Jepara - Semat'!Y44 -> 7.4337121 | I19: ='Rembang - Pantai Leran 1 (Barat'!AD59 | J19: ='Jepara - Semat'!AD44 -> 3.8825758 | N19: ='Jepara - Semat'!AG44 -> 30.384615 | O19: ='Jepara - Semat'!AH44 -> 52.272727 | P19: 1 | Q19: =Count(F19:M19) -> 4 | R19: =(Q19/9)*0.2+(D19/100)*0.2+(P19/2)*0.2+(1-(N19/100))*0.2+(1-(O19/100))*0.2 -> 0.49658557 | S19: Buruk
A20: 8 | B20: Pantai Teluk Awur | C20: JPRA.SG08 | D20: ='Jepara - Teluk Awur'!J44 -> 29.356061 | E20: =D20/sqrt(Q20) -> 13.128429 | F20: ='Jepara - Teluk Awur'!O44 -> 2.6988636 | G20: ='Jepara - Teluk Awur'!T44 -> 8.5227273 | H20: ='Jepara - Teluk Awur'!Y44 -> 6.3920455 | I20: ='Jepara - Teluk Awur'!AD44 -> 11.174242 | J20: ='Jepara - Teluk Awur'!AI44 -> 0.56818182 | N20: ='Jepara - Teluk Awur'!AL44 -> 14.038462 | O20: ='Jepara - Teluk Awur'!AM44 -> 19.545455 | P20: 1 | Q20: =Count(F20:M20) -> 5 | R20: =(Q20/9)*0.2+(D20/100)*0.2+(P20/2)*0.2+(1-(N20/100))*0.2+(1-(O20/100))*0.2 -> 0.6026554 | S20: Sedang
A21: 9 | B21: Pantai Salor | C21: JPRA.SG09 | D21: ='Jepara - Salor'!J44 -> 19.318182 | E21: =D21/sqrt(Q21) -> 7.8866147 | F21: ='Jepara - Salor'!O44 -> 1.1837121 | G21: ='Jepara - Salor'!T44 -> 8.9015152 | H21: ='Jepara - Salor'!Y44 -> 6.1079545 | I21: ='Jepara - Salor'!AD44 -> 1.0416667 | J21: ='Jepara - Salor'!AI44 -> 0.80492424 | M21: ='Jepara - Salor'!AN44 -> 1.2784091 | N21: ='Jepara - Salor'!AQ44 -> 18.846154 | O21: ='Jepara - Salor'!AR44 -> 23.939394 | P21: 1 | Q21: =Count(F21:M21) -> 6 | R21: =(Q21/9)*0.2+(D21/100)*0.2+(P21/2)*0.2+(1-(N21/100))*0.2+(1-(O21/100))*0.2 -> 0.5863986 | S21: Sedang
C22: Rata - Rata | D22: =AVERAGE(D13:D21) -> 32.1008 | F22: =AVERAGE(F13:F21) -> 1.858428 | G22: =AVERAGE(G13:G21) -> 12.803662 | H22: =AVERAGE(H13:H21) -> 6.303267 | I22: =AVERAGE(I13:I21) -> 15.246212 | J22: =AVERAGE(J13:J21) -> 2.0596591 | M22: =AVERAGE(M13:M21) -> 1.467803 | N22: =AVERAGE(N13:N21) -> 13.808599 | O22: =AVERAGE(O13:O21) -> 27.525253 | R22: =AVERAGE(R13:R21) -> 0.60499069 | S22: Sedang
C23: STDEV | D23: =STDEV(D13:D21) -> 17.963531
A27: No | B27: Lokasi/Pulau | C27: Stasiun | D27: Rata-Rata Penutupan Lamun (%) | E27: STD EROR | F27: Dominansi Jenis (%) | N27: Nilai Parameter Pendukung (Rata-rata) | P27: Kecerahan Perairan | Q27: Jumlah Spesies | R27: IKEL/SEQI | S27: Status IKEL
F28: Ea | G28: Th | H28: Cr | I28: Os | J28: Hu | K28: Si | L28: Hp | M28: Ho | N28: Tutupan Makroalga (%) | O28: Tutupan Perifiton (%)
A29: 1 | B29: Pantai Tebeng 1 | C29: CLCP.SG01 | D29: ='Cilacap - Tebeng 1'!J44 -> 35.814394 | E29: =D29/sqrt(Q29) -> 20.67745 | F29: ='Rembang - Pulau Marongan'!O73 | G29: ='Cilacap - Tebeng 1'!T44 -> 26.041667 | H29: ='Rembang - Pulau Marongan'!Y73 | I29: ='Rembang - Pulau Marongan'!AI73 | L29: ='Cilacap - Tebeng 1'!AI44 -> 7.6893939 | M29: ='Cilacap - Tebeng 1'!AD44 -> 2.0833333 | N29: ='Cilacap - Tebeng 1'!AQ44 -> 13.939394 | O29: ='Cilacap - Tebeng 1'!AR44 -> 28.939394 | P29: 2 | Q29: =Count(F29:M29) -> 3 | R29: =(Q29/9)*0.2+(D29/100)*0.2+(P29/2)*0.2+(1-(N29/100))*0.2+(1-(O29/100))*0.2 -> 0.65253788 | S29: Sedang
A30: 2 | B30: Pantai Tebeng 2 | C30: CLCP.SG02 | D30: ='Cilacap - Tebeng 2'!J44 -> 36.458333 | E30: =D30/sqrt(Q30) -> 36.458333 | G30: ='Cilacap - Tebeng 2'!T44 -> 36.458333 | H30: ='Rembang - Pantai Leran 1 (Barat'!Y73 | I30: ='Rembang - Pantai Leran 1 (Barat'!AD73 | N30: ='Cilacap - Tebeng 2'!AQ44 -> 17.878788 | O30: ='Cilacap - Tebeng 2'!AR44 -> 32.727273 | P30: 2 | Q30: =Count(F30:M30) -> 1 | R30: =(Q30/9)*0.2+(D30/100)*0.2+(P30/2)*0.2+(1-(N30/100))*0.2+(1-(O30/100))*0.2 -> 0.59392677 | S30: Sedang
A31: 3 | B31: Pantai Karang Tengah | C31: CLCP.SG03 | D31: ='Cilacap - Karangtengah'!J44 -> 36.214015 | E31: =D31/sqrt(Q31) -> 18.107008 | F31: ='Cilacap - Karangtengah'!O44 -> 1.1363636 | G31: ='Cilacap - Karangtengah'!T44 -> 26.704545 | H31: ='Rembang - Pantai Leran 2 (Timur'!Y73 | I31: ='Rembang - Pantai Leran 2 (Timur'!AD73 | L31: ='Cilacap - Karangtengah'!AI44 -> 7.0075758 | M31: ='Cilacap - Karangtengah'!AD44 -> 1.2897727 | N31: ='Cilacap - Karangtengah'!AQ44 -> 23.333333 | O31: ='Cilacap - Karangtengah'!AR44 -> 40.30303 | P31: 1 | Q31: =Count(F31:M31) -> 4 | R31: =(Q31/9)*0.2+(D31/100)*0.2+(P31/2)*0.2+(1-(N31/100))*0.2+(1-(O31/100))*0.2 -> 0.53404419 | S31: Sedang
C32: Rata - Rata | D32: =AVERAGE(D29:D31) -> 36.162247 | F32: =AVERAGE(F29:F31) -> 1.1363636 | G32: =AVERAGE(G29:G31) -> 29.734848 | L32: =AVERAGE(L29:L31) -> 7.3484848 | M32: =AVERAGE(M29:M31) -> 1.686553 | N32: =AVERAGE(N29:N31) -> 18.383838 | O32: =AVERAGE(O29:O31) -> 33.989899 | R32: =AVERAGE(R29:R31) -> 0.59350295 | S32: Sedang
C33: STDEV | D33: =STDEV(D29:D31) -> 0.325076
B44: Lokasi/Pulau | C44: Stasiun | D44: Ea | E44: Th | F44: Cr | G44: Os | H44: Hu | I44: Si | J44: Hp | K44: Ho
B45: Pulau Marongan | C45: RMBG.SG01 | D45: 6.2026515 | E45: 13.967803 | F45: 5.4450758 | G45: 11.789773 | K45: 2.7935606
B46: Pantai Leran 1 (Barat) | C46: RMBG.SG02 | D46: 5.5397727 | E46: 12.594697 | F46: 4.782197 | G46: 9.1382576
B47: Pantai Leran 2 (Timur) | C47: RMBG.SG03 | D47: 1.7992424 | E47: 10.653409 | F47: 2.5568182 | G47: 19.270833
B48: Pantai Prawean | C48: JPRA.SG01 | D48: 0.89962121 | E48: 10.700758 | F48: 4.8295455 | G48: 22.537879 | H48: 4.7348485 | K48: 1.5151515
B49: Pantai Kayu Apung | C49: JPRA.SG02 | D49: 1.0890152 | E49: 18.986742 | F49: 4.2613636 | G49: 16.761364 | H49: 0.9469697 | I49: 0.71022727
B50: Pulau Panjang | C50: JPRA.SG03 | D50: 1.657197 | E50: 17.518939 | F50: 7.3863636 | G50: 38.257576 | H50: 1.4204545 | K50: 1.6098485
B51: Pantai Ujung Piring | C51: JPRA.SG04 | D51: 1.8465909 | E51: 10.443182 | F51: 4.3560606
B52: Pantai Blebak | C52: JPRA.SG05 | E52: 9.3825758 | F52: 9.6590909 | G52: 1.7045455
B53: Pantai Kartini | C53: JPRA.SG06 | D53: 1.9886364 | E53: 9.0909091
B54: Pantai Semat | C54: JPRA.SG07 | D54: 3.5037879 | E54: 21.685606 | F54: 7.4337121 | H54: 3.8825758
B55: Pantai Teluk Awur | C55: JPRA.SG08 | D55: 2.6988636 | E55: 8.5227273 | F55: 6.3920455 | G55: 11.174242 | H55: 0.56818182
B56: Pantai Salor | C56: JPRA.SG09 | D56: 1.1837121 | E56: 8.9015152 | F56: 6.1079545 | G56: 1.0416667 | H56: 0.80492424 | K56: 1.2784091
...

Sheet Parameter Perairan
A1: Stasiun | B1: Lokasi | C1: Parameter Perairan
C2: Salinitas | D2: Suhu | E2: pH
A3: RMBG.SG01 | B3: Pulau Marongan | C3: 31 | D3: 32.2 | E3: 7.5
A4: RMBG.SG02 | B4: Pantai Leran 1 (Barat) | C4: 25 | D4: 32 | E4: 7.3
A5: RMBG.SG03 | B5: Pantai Leran 2 (Timur) | C5: 29 | D5: 33.6 | E5: 7.4
A6: JPRA.SG01 | B6: Pantai Prawean | C6: 33 | D6: 33.7 | E6: 7.3
A7: JPRA.SG02 | B7: Pantai Kayu Apung | C7: 32 | D7: 31.5 | E7: 7.1
A8: JPRA.SG03 | B8: Pulau Panjang | C8: 35 | D8: 46051 | E8: 46180
A9: JPRA.SG04 | B9: Pantai Ujung Piring | C9: 30 | D9: 31.2 | E9: 7.2
A10: JPRA.SG05 | B10: Pantai Blebak | C10: 33 | D10: 31.5 | E10: 7.5
A11: JPRA.SG06 | B11: Pantai Kartini | C11: 34 | D11: 30.8 | E11: 7.4
A12: JPRA.SG07 | B12: Pantai Semat | C12: 32 | D12: 31.3 | E12: 7.5
A13: JPRA.SG08 | B13: Pantai Teluk Awur | C13: 32 | D13: 32.6 | E13: 7.5
A14: JPRA.SG09 | B14: Pantai Salor | C14: 34 | D14: 33.1 | E14: 7.1
... A17: CLCP.SG03 | B17: Pantai Karang Tengah | C17: 35 | D17: 32.2 | E17: 7.5
B18: Marina | C18: 33 | D18: 32.8 | E18: 7.2

Sheet Jepara - Prawean
A1: Jepara
A2: Stasiun | B2: Pantai Prawean | F2: Tanggal | K2: Catatan:
A3: Pengamat | B3: Dio, Reza, Humam, Agus | F3: Waktu
A5: Informasi umum: | D5: Cuaca | G5: Kecerahan | K5: Sungai | U5: Kedalaman
D6: Mangove | G6: Dermaga | U6: Aktivitas | V6: Jalur Kapal dan Pariwisata
A8: Transek | C8: Koordinat | E8: Substrat | F8: Nilai Penutupan Lamun | J8: Rata - Rata Penutupan Lamun (%) | K8: Nilai penutupan lamun per jenis | AO8: Kekayaan Spesies | AP8: Kerapatan Ea (m2) | AQ8: Penutupan | AT8: Kecerahan air | AU8: Catatan
A9: Line | B9: Meter | C9: Lat | D9: Long | F9: Kotak | L9: Ea | O9: Rata - Rata (%) | Q9: Th | T9: Rata - Rata (%) | V9: Cr | Y9: Rata - Rata (%) | Z9: Ho | AD9: Rata-Rata (%) | AE9: Hu | AI9: Rata - Rata (%) | AJ9: Os | AN9: Rata - Rata (%) | AQ9: Makroalga | AR9: Epifit | AS9: Tipe
F10: 1 | G10: 2 | H10: 3 | I10: 4 | K10: 1 | L10: 2 | M10: 3 | N10: 4 | P10: 1 | Q10: 2 | R10: 3 | S10: 4 | U10: 1 | V10: 2 | W10: 3 | X10: 4 | Z10: 1 | AA10: 2 | AB10: 3 | AC10: 4 | AE10: 1 | AF10: 2 | AG10: 3 | AH10: 4 | AJ10: 1 | AK10: 2 | AL10: 3 | AM10: 4 | AR10: (%) | AS10: Substrat
A11: 1 | B11: 0 | C11: -6.564077° E, 110.653732° S | F11: =sum(K11,P11,U11,Z11,AE11,AJ11) -> 0 | G11: =sum(L11,Q11,V11,AA11,AF11,AK11) -> 37.5 | H11: =sum(M11,R11,W11,AB11,AG11,AL11) -> 37.5 | I11: =sum(N11,S11,X11,AC11,AH11,AM11) -> 25 | J11: =AVERAGE(F11:I11) -> 25 | K11: 0 | L11: 0 | M11: 0 | N11: 0 | O11: =AVERAGE(K11:N11) -> 0 | P11: 0 | Q11: 0 | R11: 0 | S11: 0 | T11: =AVERAGE(P11:S11) -> 0 | U11: 0 | V11: 0 | W11: 0 | X11: 0 | Y11: =AVERAGE(U11:X11) -> 0 | Z11: 0 | AA11: 0 | AB11: 0 | AC11: 0 | AD11: =AVERAGE(Z11:AC11) -> 0 | AE11: 0 | AF11: 25 | AG11: 25 | AH11: 12.5 | AI11: =AVERAGE(AE11:AH11) -> 15.625 | AJ11: 0 | AK11: 12.5 | AL11: 12.5 | AM11: 12.5 | AN11: =AVERAGE(AJ11:AM11) -> 9.375 | AO11: =SUM((O11>0)*1,(T11>0)*1,(Y11>0)*1,(AD11>0)*1,(AI11>0)*1,(AN11>0)*1) -> 2 | AQ11: 15 | AR11: 50 | AS11: Lumpur | AT11: Cerah
B12: 10 | F12: =sum(K12,P12,U12,Z12,AE12,AJ12) -> 100 | G12: =sum(L12,Q12,V12,AA12,AF12,AK12) -> 75 | H12: =sum(M12,R12,W12,AB12,AG12,AL12) -> 75 | I12: =sum(N12,S12,X12,AC12,AH12,AM12) -> 50 | J12: =AVERAGE(F12:I12) -> 75 | K12: 0 | L12: 0 | M12: 0 | N12: 0 | O12: =AVERAGE(K12:N12) -> 0 | P12: 75 | Q12: 50 | R12: 50 | S12: 25 | T12: =AVERAGE(P12:S12) -> 50 | U12: 0 | V12: 0 | W12: 0 | X12: 0 | Y12: =AVERAGE(U12:X12) -> 0 | Z12: 0 | AA12: 0 | AB12: 0 | AC12: 0 | AD12: =AVERAGE(Z12:AC12) -> 0 | AE12: 0 | AF12: 0 | AG12: 0 | AH12: 0 | AI12: =AVERAGE(AE12:AH12) -> 0 | AJ12: 25 | AK12: 25 | AL12: 25 | AM12: 25 | AN12: =AVERAGE(AJ12:AM12) -> 25 | AO12: =SUM((O12>0)*1,(T12>0)*1,(Y12>0)*1,(AD12>0)*1,(AI12>0)*1,(AN12>0)*1) -> 2 | AQ12: 10 | AR12: 20
B13: 20 | F13: =sum(K13,P13,U13,Z13,AE13,AJ13) -> 100 | G13: =sum(L13,Q13,V13,AA13,AF13,AK13) -> 87.5 | H13: =sum(M13,R13,W13,AB13,AG13,AL13) -> 87.5 | I13: =sum(N13,S13,X13,AC13,AH13,AM13) -> 87.5 | J13: =AVERAGE(F13:I13) -> 90.625 | K13: 0 | L13: 0 | M13: 0 | N13: 0 | O13: =AVERAGE(K13:N13) -> 0 | P13: 25 | Q13: 50 | R13: 50 | S13: 50 | T13: =AVERAGE(P13:S13) -> 43.75 | U13: 50 | V13: 25 | W13: 25 | X13: 25 | Y13: =AVERAGE(U13:X13) -> 31.25 | Z13: 25 | AA13: 12.5 | AB13: 12.5 | AC13: 12.5 | AD13: =AVERAGE(Z13:AC13) -> 15.625 | AE13: 0 | AF13: 0 | AG13: 0 | AH13: 0 | AI13: =AVERAGE(AE13:AH13) -> 0 | AJ13: 0 | AK13: 0 | AL13: 0 | AM13: 0 | AN13: =AVERAGE(AJ13:AM13) -> 0 | AO13: =SUM((O13>0)*1,(T13>0)*1,(Y13>0)*1,(AD13>0)*1,(AI13>0)*1,(AN13>0)*1) -> 3 | AQ13: 15 | AR13: 50
B14: 30 | F14: =sum(K14,P14,U14,Z14,AE14,AJ14) -> 87.5 | G14: =sum(L14,Q14,V14,AA14,AF14,AK14) -> 81.25 | H14: =sum(M14,R14,W14,AB14,AG14,AL14) -> 43.75 | I14: =sum(N14,S14,X14,AC14,AH14,AM14) -> 43.75 | J14: =AVERAGE(F14:I14) -> 64.0625 | K14: 12.5 | L14: 6.25 | M14: 6.25 | N14: 6.25 | O14: =AVERAGE(K14:N14) -> 7.8125 | P14: 50 | Q14: 50 | R14: 25 | S14: 25 | T14: =AVERAGE(P14:S14) -> 37.5 | U14: 0 | V14: 0 | W14: 0 | X14: 0 | Y14: =AVERAGE(U14:X14) -> 0 | Z14: 0 | AA14: 0 | AB14: 0 | AC14: 0 | AD14: =AVERAGE(Z14:AC14) -> 0 | AE14: 25 | AF14: 25 | AG14: 12.5 | AH14: 12.5 | AI14: =AVERAGE(AE14:AH14) -> 18.75 | AJ14: 0 | AK14: 0 | AL14: 0 | AM14: 0 | AN14: =AVERAGE(AJ14:AM14) -> 0 | AO14: =SUM((O14>0)*1,(T14>0)*1,(Y14>0)*1,(AD14>0)*1,(AI14>0)*1,(AN14>0)*1) -> 3 | AP14: 20 | AQ14: 10 | AR14: 30
B15: 40 | F15: =sum(K15,P15,U15,Z15,AE15,AJ15) -> 100 | G15: =sum(L15,Q15,V15,AA15,AF15,AK15) -> 75 | H15: =sum(M15,R15,W15,AB15,AG15,AL15) -> 56.25 | I15: =sum(N15,S15,X15,AC15,AH15,AM15) -> 56.25 | J15: =AVERAGE(F15:I15) -> 71.875 | K15: 0 | L15: 0 | M15: 0 | N15: 0 | O15: =AVERAGE(K15:N15) -> 0 | P15: 75 | Q15: 50 | R15: 50 | S15: 50 | T15: =AVERAGE(P15:S15) -> 56.25 | U15: 25 | V15: 25 | W15: 6.25 | X15: 6.25 | Y15: =AVERAGE(U15:X15) -> 15.625 | Z15: 0 | AA15: 0 | AB15: 0 | AC15: 0 | AD15: =AVERAGE(Z15:AC15) -> 0 | AE15: 0 | AF15: 0 | AG15: 0 | AH15: 0 | AI15: =AVERAGE(AE15:AH15) -> 0 | AJ15: 0 | AK15: 0 | AL15: 0 | AM15: 0 | AN15: =AVERAGE(AJ15:AM15) -> 0 | AO15: =SUM((O15>0)*1,(T15>0)*1,(Y15>0)*1,(AD15>0)*1,(AI15>0)*1,(AN15>0)*1) -> 2 | AQ15: 40 | AR15: 40
B16: 50 | F16: =sum(K16,P16,U16,Z16,AE16,AJ16) -> 56.25 | G16: =sum(L16,Q16,V16,AA16,AF16,AK16) -> 81.25 | H16: =sum(M16,R16,W16,AB16,AG16,AL16) -> 50 | I16: =sum(N16,S16,X16,AC16,AH16,AM16) -> 56.25 | J16: =AVERAGE(F16:I16) -> 60.9375 | K16: 12.5 | L16: 12.5 | M16: 6.25 | N16: 0 | O16: =AVERAGE(K16:N16) -> 7.8125 | P16: 0 | Q16: 0 | R16: 0 | S16: 0 | T16: =AVERAGE(P16:S16) -> 0 | U16: 0 | V16: 0 | W16: 0 | X16: 0 | Y16: =AVERAGE(U16:X16) -> 0 | Z16: 6.25 | AA16: 6.25 | AB16: 6.25 | AC16: 6.25 | AD16: =AVERAGE(Z16:AC16) -> 6.25 | AE16: 12.5 | AF16: 12.5 | AG16: 12.5 | AH16: 25 | AI16: =AVERAGE(AE16:AH16) -> 15.625 | AJ16: 25 | AK16: 50 | AL16: 25 | AM16: 25 | AN16: =AVERAGE(AJ16:AM16) -> 31.25 | AO16: =SUM((O16>0)*1,(T16>0)*1,(Y16>0)*1,(AD16>0)*1,(AI16>0)*1,(AN16>0)*1) -> 4 | AP16: 20 | AQ16: 10 | AR16: 60
B17: 60 | F17: =sum(K17,P17,U17,Z17,AE17,AJ17) -> 87.5 | G17: =sum(L17,Q17,V17,AA17,AF17,AK17) -> 62.5 | H17: =sum(M17,R17,W17,AB17,AG17,AL17) -> 75 | I17: =sum(N17,S17,X17,AC17,AH17,AM17) -> 50 | J17: =AVERAGE(F17:I17) -> 68.75 | K17: 0 | L17: 0 | M17: 0 | N17: 0 | O17: =AVERAGE(K17:N17) -> 0 | P17: 12.5 | Q17: 12.5 | R17: 12.5 | S17: 12.5 | T17: =AVERAGE(P17:S17) -> 12.5 | U17: 0 | V17: 0 | W17: 0 | X17: 0 | Y17: =AVERAGE(U17:X17) -> 0 | Z17: 0 | AA17: 0 | AB17: 0 | AC17: 0 | AD17: =AVERAGE(Z17:AC17) -> 0 | AE17: 25 | AF17: 12.5 | AG17: 12.5 | AH17: 12.5 | AI17: =AVERAGE(AE17:AH17) -> 15.625 | AJ17: 50 | AK17: 37.5 | AL17: 50 | AM17: 25 | AN17: =AVERAGE(AJ17:AM17) -> 40.625 | AO17: =SUM((O17>0)*1,(T17>0)*1,(Y17>0)*1,(AD17>0)*1,(AI17>0)*1,(AN17>0)*1) -> 3 | AQ17: 10 | AR17: 20
B18: 70 | F18: =sum(K18,P18,U18,Z18,AE18,AJ18) -> 37.5 | G18: =sum(L18,Q18,V18,AA18,AF18,AK18) -> 37.5 | H18: =sum(M18,R18,W18,AB18,AG18,AL18) -> 37.5 | I18: =sum(N18,S18,X18,AC18,AH18,AM18) -> 37.5 | J18: =AVERAGE(F18:I18) -> 37.5 | K18: 0 | L18: 0 | M18: 0 | N18: 0 | O18: =AVERAGE(K18:N18) -> 0 | P18: 0 | Q18: 0 | R18: 0 | S18: 0 | T18: =AVERAGE(P18:S18) -> 0 | U18: 12.5 | V18: 12.5 | W18: 12.5 | X18: 12.5 | Y18: =AVERAGE(U18:X18) -> 12.5 | Z18: 0 | AA18: 0 | AB18: 0 | AC18: 0 | AD18: =AVERAGE(Z18:AC18) -> 0 | AE18: 0 | AF18: 0 | AG18: 0 | AH18: 0 | AI18: =AVERAGE(AE18:AH18) -> 0 | AJ18: 25 | AK18: 25 | AL18: 25 | AM18: 25 | AN18: =AVERAGE(AJ18:AM18) -> 25 | AO18: =SUM((O18>0)*1,(T18>0)*1,(Y18>0)*1,(AD18>0)*1,(AI18>0)*1,(AN18>0)*1) -> 2 | AQ18: 10 | AR18: 30
B19: 80 | F19: =sum(K19,P19,U19,Z19,AE19,AJ19) -> 25 | G19: =sum(L19,Q19,V19,AA19,AF19,AK19) -> 25 | H19: =sum(M19,R19,W19,AB19,AG19,AL19) -> 25 | I19: =sum(N19,S19,X19,AC19,AH19,AM19) -> 25 | J19: =AVERAGE(F19:I19) -> 25 | K19: 0 | L19: 0 | M19: 0 | N19: 0 | O19: =AVERAGE(K19:N19) -> 0 | P19: 0 | Q19: 0 | R19: 0 | S19: 0 | T19: =AVERAGE(P19:S19) -> 0 | U19: 0 | V19: 0 | W19: 0 | X19: 0 | Y19: =AVERAGE(U19:X19) -> 0 | Z19: 0 | AA19: 0 | AB19: 0 | AC19: 0 | AD19: =AVERAGE(Z19:AC19) -> 0 | AE19: 0 | AF19: 0 | AG19: 0 | AH19: 0 | AI19: =AVERAGE(AE19:AH19) -> 0 | AJ19: 25 | AK19: 25 | AL19: 25 | AM19: 25 | AN19: =AVERAGE(AJ19:AM19) -> 25 | AO19: =SUM((O19>0)*1,(T19>0)*1,(Y19>0)*1,(AD19>0)*1,(AI19>0)*1,(AN19>0)*1) -> 1 | AQ19: 10 | AR19: 30
B20: 90 | F20: =sum(K20,P20,U20,Z20,AE20,AJ20) -> 50 | G20: =sum(L20,Q20,V20,AA20,AF20,AK20) -> 50 | H20: =sum(M20,R20,W20,AB20,AG20,AL20) -> 25 | I20: =sum(N20,S20,X20,AC20,AH20,AM20) -> 50 | J20: =AVERAGE(F20:I20) -> 43.75 | K20: 0 | L20: 0 | M20: 0 | N20: 0 | O20: =AVERAGE(K20:N20) -> 0 | P20: 0 | Q20: 0 | R20: 0 | S20: 0 | T20: =AVERAGE(P20:S20) -> 0 | U20: 0 | V20: 0 | W20: 0 | X20: 0 | Y20: =AVERAGE(U20:X20) -> 0 | Z20: 0 | AA20: 0 | AB20: 0 | AC20: 0 | AD20: =AVERAGE(Z20:AC20) -> 0 | AE20: 0 | AF20: 0 | AG20: 0 | AH20: 0 | AI20: =AVERAGE(AE20:AH20) -> 0 | AJ20: 50 | AK20: 50 | AL20: 25 | AM20: 50 | AN20: =AVERAGE(AJ20:AM20) -> 43.75 | AO20: =SUM((O20>0)*1,(T20>0)*1,(Y20>0)*1,(AD20>0)*1,(AI20>0)*1,(AN20>0)*1) -> 1 | AQ20: 20 | AR20: 50
B21: 100 | C21: -6.565409°E, 110.652513°S | F21: =sum(K21,P21,U21,Z21,AE21,AJ21) -> 50 | G21: =sum(L21,Q21,V21,AA21,AF21,AK21) -> 50 | H21: =sum(M21,R21,W21,AB21,AG21,AL21) -> 50 | I21: =sum(N21,S21,X21,AC21,AH21,AM21) -> 75 | J21: =AVERAGE(F21:I21) -> 56.25 | K21: 0 | L21: 0 | M21: 0 | N21: 0 | O21: =AVERAGE(K21:N21) -> 0 | P21: 0 | Q21: 0 | R21: 0 | S21: 0 | T21: =AVERAGE(P21:S21) -> 0 | U21: 0 | V21: 0 | W21: 0 | X21: 0 | Y21: =AVERAGE(U21:X21) -> 0 | Z21: 0 | AA21: 0 | AB21: 0 | AC21: 0 | AD21: =AVERAGE(Z21:AC21) -> 0 | AE21: 0 | AF21: 0 | AG21: 0 | AH21: 0 | AI21: =AVERAGE(AE21:AH21) -> 0 | AJ21: 50 | AK21: 50 | AL21: 50 | AM21: 75 | AN21: =AVERAGE(AJ21:AM21) -> 56.25 | AO21: =SUM((O21>0)*1,(T21>0)*1,(Y21>0)*1,(AD21>0)*1,(AI21>0)*1,(AN21>0)*1) -> 1 | AQ21: 10 | AR21: 30
A22: 2 | B22: 0 | C22: -6.563955° E, 110.653269° S | F22: =sum(K22,P22,U22,Z22,AE22,AJ22) -> 25 | G22: =sum(L22,Q22,V22,AA22,AF22,AK22) -> 0 | H22: =sum(M22,R22,W22,AB22,AG22,AL22) -> 12.5 | I22: =sum(N22,S22,X22,AC22,AH22,AM22) -> 12.5 | J22: =AVERAGE(F22:I22) -> 12.5 | K22: 0 | L22: 0 | M22: 0 | N22: 0 | O22: =AVERAGE(K22:N22) -> 0 | P22: 0 | Q22: 0 | R22: 0 | S22: 0 | T22: =AVERAGE(P22:S22) -> 0 | U22: 0 | V22: 0 | W22: 0 | X22: 0 | Y22: =AVERAGE(U22:X22) -> 0 | Z22: 0 | AA22: 0 | AB22: 0 | AC22: 0 | AD22: =AVERAGE(Z22:AC22) -> 0 | AE22: 0 | AF22: 0 | AG22: 0 | AH22: 0 | AI22: =AVERAGE(AE22:AH22) -> 0 | AJ22: 25 | AK22: 0 | AL22: 12.5 | AM22: 12.5 | AN22: =AVERAGE(AJ22:AM22) -> 12.5 | AO22: =SUM((O22>0)*1,(T22>0)*1,(Y22>0)*1,(AD22>0)*1,(AI22>0)*1,(AN22>0)*1) -> 1 | AQ22: 15 | AR22: 20 | AS22: Lumpur | AT22: Cerah
B23: 10 | F23: =sum(K23,P23,U23,Z23,AE23,AJ23) -> 50 | G23: =sum(L23,Q23,V23,AA23,AF23,AK23) -> 50 | H23: =sum(M23,R23,W23,AB23,AG23,AL23) -> 50 | I23: =sum(N23,S23,X23,AC23,AH23,AM23) -> 75 | J23: =AVERAGE(F23:I23) -> 56.25 | K23: 0 | L23: 0 | M23: 0 | N23: 0 | O23: =AVERAGE(K23:N23) -> 0 | P23: 25 | Q23: 25 | R23: 25 | S23: 50 | T23: =AVERAGE(P23:S23) -> 31.25 | U23: 0 | V23: 0 | W23: 0 | X23: 0 | Y23: =AVERAGE(U23:X23) -> 0 | Z23: 0 | AA23: 0 | AB23: 0 | AC23: 0 | AD23: =AVERAGE(Z23:AC23) -> 0 | AE23: 0 | AF23: 0 | AG23: 0 | AH23: 0 | AI23: =AVERAGE(AE23:AH23) -> 0 | AJ23: 25 | AK23: 25 | AL23: 25 | AM23: 25 | AN23: =AVERAGE(AJ23:AM23) -> 25 | AO23: =SUM((O23>0)*1,(T23>0)*1,(Y23>0)*1,(AD23>0)*1,(AI23>0)*1,(AN23>0)*1) -> 2 | AQ23: 20 | AR23: 50
B24: 20 | F24: =sum(K24,P24,U24,Z24,AE24,AJ24) -> 87.5 | G24: =sum(L24,Q24,V24,AA24,AF24,AK24) -> 62.5 | H24: =sum(M24,R24,W24,AB24,AG24,AL24) -> 87.5 | I24: =sum(N24,S24,X24,AC24,AH24,AM24) -> 87.5 | J24: =AVERAGE(F24:I24) -> 81.25 | K24: 0 | L24: 0 | M24: 0 | N24: 0 | O24: =AVERAGE(K24:N24) -> 0 | P24: 25 | Q24: 25 | R24: 25 | S24: 25 | T24: =AVERAGE(P24:S24) -> 25 | U24: 12.5 | V24: 0 | W24: 12.5 | X24: 12.5 | Y24: =AVERAGE(U24:X24) -> 9.375 | Z24: 0 | AA24: 0 | AB24: 0 | AC24: 0 | AD24: =AVERAGE(Z24:AC24) -> 0 | AE24: 12.5 | AF24: 12.5 | AG24: 12.5 | AH24: 12.5 | AI24: =AVERAGE(AE24:AH24) -> 12.5 | AJ24: 37.5 | AK24: 25 | AL24: 37.5 | AM24: 37.5 | AN24: =AVERAGE(AJ24:AM24) -> 34.375 | AO24: =SUM((O24>0)*1,(T24>0)*1,(Y24>0)*1,(AD24>0)*1,(AI24>0)*1,(AN24>0)*1) -> 4 | AQ24: 25 | AR24: 20
B25: 30 | F25: =sum(K25,P25,U25,Z25,AE25,AJ25) -> 0 | G25: =sum(L25,Q25,V25,AA25,AF25,AK25) -> 0 | H25: =sum(M25,R25,W25,AB25,AG25,AL25) -> 12.5 | I25: =sum(N25,S25,X25,AC25,AH25,AM25) -> 12.5 | J25: =AVERAGE(F25:I25) -> 6.25 | K25: 0 | L25: 0 | M25: 0 | N25: 0 | O25: =AVERAGE(K25:N25) -> 0 | P25: 0 | Q25: 0 | R25: 12.5 | S25: 12.5 | T25: =AVERAGE(P25:S25) -> 6.25 | U25: 0 | V25: 0 | W25: 0 | X25: 0 | Y25: =AVERAGE(U25:X25) -> 0 | Z25: 0 | AA25: 0 | AB25: 0 | AC25: 0 | AD25: =AVERAGE(Z25:AC25) -> 0 | AE25: 0 | AF25: 0 | AG25: 0 | AH25: 0 | AI25: =AVERAGE(AE25:AH25) -> 0 | AJ25: 0 | AK25: 0 | AL25: 0 | AM25: 0 | AN25: =AVERAGE(AJ25:AM25) -> 0 | AO25: =SUM((O25>0)*1,(T25>0)*1,(Y25>0)*1,(AD25>0)*1,(AI25>0)*1,(AN25>0)*1) -> 1 | AQ25: 25 | AR25: 30
B26: 40 | F26: =sum(K26,P26,U26,Z26,AE26,AJ26) -> 25 | G26: =sum(L26,Q26,V26,AA26,AF26,AK26) -> 25 | H26: =sum(M26,R26,W26,AB26,AG26,AL26) -> 37.5 | I26: =sum(N26,S26,X26,AC26,AH26,AM26) -> 37.5 | J26: =AVERAGE(F26:I26) -> 31.25 | K26: 0 | L26: 0 | M26: 0 | N26: 0 | O26: =AVERAGE(K26:N26) -> 0 | P26: 12.5 | Q26: 12.5 | R26: 12.5 | S26: 12.5 | T26: =AVERAGE(P26:S26) -> 12.5 | U26: 0 | V26: 0 | W26: 0 | X26: 0 | Y26: =AVERAGE(U26:X26) -> 0 | Z26: 0 | AA26: 0 | AB26: 0 | AC26: 0 | AD26: =AVERAGE(Z26:AC26) -> 0 | AE26: 0 | AF26: 0 | AG26: 0 | AH26: 0 | AI26: =AVERAGE(AE26:AH26) -> 0 | AJ26: 12.5 | AK26: 12.5 | AL26: 25 | AM26: 25 | AN26: =AVERAGE(AJ26:AM26) -> 18.75 | AO26: =SUM((O26>0)*1,(T26>0)*1,(Y26>0)*1,(AD26>0)*1,(AI26>0)*1,(AN26>0)*1) -> 2 | AQ26: 0 | AR26: 40
B27: 50 | F27: =sum(K27,P27,U27,Z27,AE27,AJ27) -> 62.5 | G27: =sum(L27,Q27,V27,AA27,AF27,AK27) -> 75 | H27: =sum(M27,R27,W27,AB27,AG27,AL27) -> 50 | I27: =sum(N27,S27,X27,AC27,AH27,AM27) -> 50 | J27: =AVERAGE(F27:I27) -> 59.375 | K27: 0 | L27: 0 | M27: 0 | N27: 0 | O27: =AVERAGE(K27:N27) -> 0 | P27: 0 | Q27: 0 | R27: 0 | S27: 0 | T27: =AVERAGE(P27:S27) -> 0 | U27: 12.5 | V27: 25 | W27: 12.5 | X27: 25 | Y27: =AVERAGE(U27:X27) -> 18.75 | Z27: 0 | AA27: 0 | AB27: 0 | AC27: 0 | AD27: =AVERAGE(Z27:AC27) -> 0 | AE27: 0 | AF27: 0 | AG27: 0 | AH27: 0 | AI27: =AVERAGE(AE27:AH27) -> 0 | AJ27: 50 | AK27: 50 | AL27: 37.5 | AM27: 25 | AN27: =AVERAGE(AJ27:AM27) -> 40.625 | AO27: =SUM((O27>0)*1,(T27>0)*1,(Y27>0)*1,(AD27>0)*1,(AI27>0)*1,(AN27>0)*1) -> 2 | AQ27: 10 | AR27: 50
B28: 60 | F28: =sum(K28,P28,U28,Z28,AE28,AJ28) -> 75 | G28: =sum(L28,Q28,V28,AA28,AF28,AK28) -> 75 | H28: =sum(M28,R28,W28,AB28,AG28,AL28) -> 62.5 | I28: =sum(N28,S28,X28,AC28,AH28,AM28) -> 62.5 | J28: =AVERAGE(F28:I28) -> 68.75 | K28: 0 | L28: 0 | M28: 0 | N28: 0 | O28: =AVERAGE(K28:N28) -> 0 | P28: 0 | Q28: 0 | R28: 0 | S28: 0 | T28: =AVERAGE(P28:S28) -> 0 | U28: 12.5 | V28: 12.5 | W28: 12.5 | X28: 12.5 | Y28: =AVERAGE(U28:X28) -> 12.5 | Z28: 0 | AA28: 0 | AB28: 0 | AC28: 0 | AD28: =AVERAGE(Z28:AC28) -> 0 | AE28: 0 | AF28: 0 | AG28: 0 | AH28: 0 | AI28: =AVERAGE(AE28:AH28) -> 0 | AJ28: 62.5 | AK28: 62.5 | AL28: 50 | AM28: 50 | AN28: =AVERAGE(AJ28:AM28) -> 56.25 | AO28: =SUM((O28>0)*1,(T28>0)*1,(Y28>0)*1,(AD28>0)*1,(AI28>0)*1,(AN28>0)*1) -> 2 | AQ28: 15 | AR28: 40
B29: 70 | F29: =sum(K29,P29,U29,Z29,AE29,AJ29) -> 25 | G29: =sum(L29,Q29,V29,AA29,AF29,AK29) -> 31.25 | H29: =sum(M29,R29,W29,AB29,AG29,AL29) -> 31.25 | I29: =sum(N29,S29,X29,AC29,AH29,AM29) -> 12.5 | J29: =AVERAGE(F29:I29) -> 25 | K29: 0 | L29: 0 | M29: 0 | N29: 0 | O29: =AVERAGE(K29:N29) -> 0 | P29: 0 | Q29: 0 | R29: 0 | S29: 0 | T29: =AVERAGE(P29:S29) -> 0 | U29: 0 | V29: 0 | W29: 0 | X29: 0 | Y29: =AVERAGE(U29:X29) -> 0 | Z29: 0 | AA29: 0 | AB29: 0 | AC29: 0 | AD29: =AVERAGE(Z29:AC29) -> 0 | AE29: 12.5 | AF29: 6.25 | AG29: 6.25 | AH29: 0 | AI29: =AVERAGE(AE29:AH29) -> 6.25 | AJ29: 12.5 | AK29: 25 | AL29: 25 | AM29: 12.5 | AN29: =AVERAGE(AJ29:AM29) -> 18.75 | AO29: =SUM((O29>0)*1,(T29>0)*1,(Y29>0)*1,(AD29>0)*1,(AI29>0)*1,(AN29>0)*1) -> 2 | AQ29: 40 | AR29: 30
B30: 80 | F30: =sum(K30,P30,U30,Z30,AE30,AJ30) -> 62.5 | G30: =sum(L30,Q30,V30,AA30,AF30,AK30) -> 75 | H30: =sum(M30,R30,W30,AB30,AG30,AL30) -> 62.5 | I30: =sum(N30,S30,X30,AC30,AH30,AM30) -> 50 | J30: =AVERAGE(F30:I30) -> 62.5 | K30: 0 | L30: 0 | M30: 0 | N30: 0 | O30: =AVERAGE(K30:N30) -> 0 | P30: 50 | Q30: 62.5 | R30: 50 | S30: 50 | T30: =AVERAGE(P30:S30) -> 53.125 | U30: 0 | V30: 0 | W30: 0 | X30: 0 | Y30: =AVERAGE(U30:X30) -> 0 | Z30: 0 | AA30: 0 | AB30: 0 | AC30: 0 | AD30: =AVERAGE(Z30:AC30) -> 0 | AE30: 0 | AF30: 0 | AG30: 0 | AH30: 0 | AI30: =AVERAGE(AE30:AH30) -> 0 | AJ30: 12.5 | AK30: 12.5 | AL30: 12.5 | AM30: 0 | AN30: =AVERAGE(AJ30:AM30) -> 9.375 | AO30: =SUM((O30>0)*1,(T30>0)*1,(Y30>0)*1,(AD30>0)*1,(AI30>0)*1,(AN30>0)*1) -> 2 | AQ30: 40 | AR30: 40
B31: 90 | F31: =sum(K31,P31,U31,Z31,AE31,AJ31) -> 37.5 | G31: =sum(L31,Q31,V31,AA31,AF31,AK31) -> 0 | H31: =sum(M31,R31,W31,AB31,AG31,AL31) -> 25 | I31: =sum(N31,S31,X31,AC31,AH31,AM31) -> 25 | J31: =AVERAGE(F31:I31) -> 21.875 | K31: 0 | L31: 0 | M31: 0 | N31: 0 | O31: =AVERAGE(K31:N31) -> 0 | P31: 0 | Q31: 0 | R31: 0 | S31: 0 | T31: =AVERAGE(P31:S31) -> 0 | U31: 0 | V31: 0 | W31: 0 | X31: 0 | Y31: =AVERAGE(U31:X31) -> 0 | Z31: 0 | AA31: 0 | AB31: 0 | AC31: 0 | AD31: =AVERAGE(Z31:AC31) -> 0 | AE31: 12.5 | AF31: 0 | AG31: 12.5 | AH31: 12.5 | AI31: =AVERAGE(AE31:AH31) -> 9.375 | AJ31: 25 | AK31: 0 | AL31: 12.5 | AM31: 12.5 | AN31: =AVERAGE(AJ31:AM31) -> 12.5 | AO31: =SUM((O31>0)*1,(T31>0)*1,(Y31>0)*1,(AD31>0)*1,(AI31>0)*1,(AN31>0)*1) -> 2 | AQ31: 0 | AR31: 30
B32: 100 | C32: -6.564979°E , 110.652258°S | F32: =sum(K32,P32,U32,Z32,AE32,AJ32) -> 75 | G32: =sum(L32,Q32,V32,AA32,AF32,AK32) -> 87.5 | H32: =sum(M32,R32,W32,AB32,AG32,AL32) -> 75 | I32: =sum(N32,S32,X32,AC32,AH32,AM32) -> 75 | J32: =AVERAGE(F32:I32) -> 78.125 | K32: 0 | L32: 0 | M32: 0 | N32: 0 | O32: =AVERAGE(K32:N32) -> 0 | P32: 0 | Q32: 0 | R32: 0 | S32: 0 | T32: =AVERAGE(P32:S32) -> 0 | U32: 0 | V32: 0 | W32: 0 | X32: 0 | Y32: =AVERAGE(U32:X32) -> 0 | Z32: 12.5 | AA32: 25 | AB32: 12.5 | AC32: 12.5 | AD32: =AVERAGE(Z32:AC32) -> 15.625 | AE32: 25 | AF32: 25 | AG32: 12.5 | AH32: 12.5 | AI32: =AVERAGE(AE32:AH32) -> 18.75 | AJ32: 37.5 | AK32: 37.5 | AL32: 50 | AM32: 50 | AN32: =AVERAGE(AJ32:AM32) -> 43.75 | AO32: =SUM((O32>0)*1,(T32>0)*1,(Y32>0)*1,(AD32>0)*1,(AI32>0)*1,(AN32>0)*1) -> 3 | AQ32: 25 | AR32: 30
A33: 3 | B33: 0 | C33: -6.563841° E, 110.652843° S | F33: =sum(K33,P33,U33,Z33,AE33,AJ33) -> 62.5 | G33: =sum(L33,Q33,V33,AA33,AF33,AK33) -> 50 | H33: =sum(M33,R33,W33,AB33,AG33,AL33) -> 37.5 | I33: =sum(N33,S33,X33,AC33,AH33,AM33) -> 25 | J33: =AVERAGE(F33:I33) -> 43.75 | K33: 0 | L33: 0 | M33: 0 | N33: 0 | O33: =AVERAGE(K33:N33) -> 0 | P33: 0 | Q33: 0 | R33: 0 | S33: 0 | T33: =AVERAGE(P33:S33) -> 0 | U33: 0 | V33: 0 | W33: 0 | X33: 0 | Y33: =AVERAGE(U33:X33) -> 0 | Z33: 0 | AA33: 0 | AB33: 0 | AC33: 0 | AD33: =AVERAGE(Z33:AC33) -> 0 | AE33: 37.5 | AF33: 25 | AG33: 25 | AH33: 12.5 | AI33: =AVERAGE(AE33:AH33) -> 25 | AJ33: 25 | AK33: 25 | AL33: 12.5 | AM33: 12.5 | AN33: =AVERAGE(AJ33:AM33) -> 18.75 | AO33: =SUM((O33>0)*1,(T33>0)*1,(Y33>0)*1,(AD33>0)*1,(AI33>0)*1,(AN33>0)*1) -> 2 | AQ33: 10 | AR33: 0 | AS33: Lumpur | AT33: Cerah
B34: 10 | F34: =sum(K34,P34,U34,Z34,AE34,AJ34) -> 12.5 | G34: =sum(L34,Q34,V34,AA34,AF34,AK34) -> 12.5 | H34: =sum(M34,R34,W34,AB34,AG34,AL34) -> 6.25 | I34: =sum(N34,S34,X34,AC34,AH34,AM34) -> 6.25 | J34: =AVERAGE(F34:I34) -> 9.375 | K34: 0 | L34: 0 | M34: 0 | N34: 0 | O34: =AVERAGE(K34:N34) -> 0 | P34: 0 | Q34: 0 | R34: 0 | S34: 0 | T34: =AVERAGE(P34:S34) -> 0 | U34: 12.5 | V34: 12.5 | W34: 6.25 | X34: 6.25 | Y34: =AVERAGE(U34:X34) -> 9.375 | Z34: 0 | AA34: 0 | AB34: 0 | AC34: 0 | AD34: =AVERAGE(Z34:AC34) -> 0 | AE34: 0 | AF34: 0 | AG34: 0 | AH34: 0 | AI34: =AVERAGE(AE34:AH34) -> 0 | AJ34: 0 | AK34: 0 | AL34: 0 | AM34: 0 | AN34: =AVERAGE(AJ34:AM34) -> 0 | AO34: =SUM((O34>0)*1,(T34>0)*1,(Y34>0)*1,(AD34>0)*1,(AI34>0)*1,(AN34>0)*1) -> 1 | AQ34: 15 | AR34: 20
B35: 20 | F35: =sum(K35,P35,U35,Z35,AE35,AJ35) -> 12.5 | G35: =sum(L35,Q35,V35,AA35,AF35,AK35) -> 12.5 | H35: =sum(M35,R35,W35,AB35,AG35,AL35) -> 12.5 | I35: =sum(N35,S35,X35,AC35,AH35,AM35) -> 12.5 | J35: =AVERAGE(F35:I35) -> 12.5 | K35: 0 | L35: 0 | M35: 0 | N35: 0 | O35: =AVERAGE(K35:N35) -> 0 | P35: 0 | Q35: 0 | R35: 0 | S35: 0 | T35: =AVERAGE(P35:S35) -> 0 | U35: 0 | V35: 0 | W35: 0 | X35: 0 | Y35: =AVERAGE(U35:X35) -> 0 | Z35: 0 | AA35: 0 | AB35: 0 | AC35: 0 | AD35: =AVERAGE(Z35:AC35) -> 0 | AE35: 0 | AF35: 0 | AG35: 0 | AH35: 0 | AI35: =AVERAGE(AE35:AH35) -> 0 | AJ35: 12.5 | AK35: 12.5 | AL35: 12.5 | AM35: 12.5 | AN35: =AVERAGE(AJ35:AM35) -> 12.5 | AO35: =SUM((O35>0)*1,(T35>0)*1,(Y35>0)*1,(AD35>0)*1,(AI35>0)*1,(AN35>0)*1) -> 1 | AQ35: 10 | AR35: 30
B36: 30 | F36: =sum(K36,P36,U36,Z36,AE36,AJ36) -> 25 | G36: =sum(L36,Q36,V36,AA36,AF36,AK36) -> 0 | H36: =sum(M36,R36,W36,AB36,AG36,AL36) -> 0 | I36: =sum(N36,S36,X36,AC36,AH36,AM36) -> 0 | J36: =AVERAGE(F36:I36) -> 6.25 | K36: 0 | L36: 0 | M36: 0 | N36: 0 | O36: =AVERAGE(K36:N36) -> 0 | P36: 0 | Q36: 0 | R36: 0 | S36: 0 | T36: =AVERAGE(P36:S36) -> 0 | U36: 0 | V36: 0 | W36: 0 | X36: 0 | Y36: =AVERAGE(U36:X36) -> 0 | Z36: 0 | AA36: 0 | AB36: 0 | AC36: 0 | AD36: =AVERAGE(Z36:AC36) -> 0 | AE36: 0 | AF36: 0 | AG36: 0 | AH36: 0 | AI36: =AVERAGE(AE36:AH36) -> 0 | AJ36: 25 | AK36: 0 | AL36: 0 | AM36: 0 | AN36: =AVERAGE(AJ36:AM36) -> 6.25 | AO36: =SUM((O36>0)*1,(T36>0)*1,(Y36>0)*1,(AD36>0)*1,(AI36>0)*1,(AN36>0)*1) -> 1 | AQ36: 10 | AR36: 50
B37: 40 | F37: =sum(K37,P37,U37,Z37,AE37,AJ37) -> 0 | G37: =sum(L37,Q37,V37,AA37,AF37,AK37) -> 0 | H37: =sum(M37,R37,W37,AB37,AG37,AL37) -> 0 | I37: =sum(N37,S37,X37,AC37,AH37,AM37) -> 0 | J37: =AVERAGE(F37:I37) -> 0 | K37: 0 | L37: 0 | M37: 0 | N37: 0 | O37: =AVERAGE(K37:N37) -> 0 | P37: 0 | Q37: 0 | R37: 0 | S37: 0 | T37: =AVERAGE(P37:S37) -> 0 | U37: 0 | V37: 0 | W37: 0 | X37: 0 | Y37: =AVERAGE(U37:X37) -> 0 | Z37: 0 | AA37: 0 | AB37: 0 | AC37: 0 | AD37: =AVERAGE(Z37:AC37) -> 0 | AE37: 0 | AF37: 0 | AG37: 0 | AH37: 0 | AI37: =AVERAGE(AE37:AH37) -> 0 | AJ37: 0 | AK37: 0 | AL37: 0 | AM37: 0 | AN37: =AVERAGE(AJ37:AM37) -> 0 | AO37: =SUM((O37>0)*1,(T37>0)*1,(Y37>0)*1,(AD37>0)*1,(AI37>0)*1,(AN37>0)*1) -> 0 | AQ37: 10 | AR37: 30
B38: 50 | F38: =sum(K38,P38,U38,Z38,AE38,AJ38) -> 50 | G38: =sum(L38,Q38,V38,AA38,AF38,AK38) -> 50 | H38: =sum(M38,R38,W38,AB38,AG38,AL38) -> 50 | I38: =sum(N38,S38,X38,AC38,AH38,AM38) -> 50 | J38: =AVERAGE(F38:I38) -> 50 | K38: 0 | L38: 0 | M38: 0 | N38: 0 | O38: =AVERAGE(K38:N38) -> 0 | P38: 25 | Q38: 25 | R38: 25 | S38: 25 | T38: =AVERAGE(P38:S38) -> 25 | U38: 0 | V38: 0 | W38: 0 | X38: 0 | Y38: =AVERAGE(U38:X38) -> 0 | Z38: 0 | AA38: 0 | AB38: 0 | AC38: 0 | AD38: =AVERAGE(Z38:AC38) -> 0 | AE38: 0 | AF38: 0 | AG38: 0 | AH38: 0 | AI38: =AVERAGE(AE38:AH38) -> 0 | AJ38: 25 | AK38: 25 | AL38: 25 | AM38: 25 | AN38: =AVERAGE(AJ38:AM38) -> 25 | AO38: =SUM((O38>0)*1,(T38>0)*1,(Y38>0)*1,(AD38>0)*1,(AI38>0)*1,(AN38>0)*1) -> 2 | AQ38: 25 | AR38: 30
B39: 60 | F39: =sum(K39,P39,U39,Z39,AE39,AJ39) -> 50 | G39: =sum(L39,Q39,V39,AA39,AF39,AK39) -> 37.5 | H39: =sum(M39,R39,W39,AB39,AG39,AL39) -> 25 | I39: =sum(N39,S39,X39,AC39,AH39,AM39) -> 25 | J39: =AVERAGE(F39:I39) -> 34.375 | K39: 0 | L39: 0 | M39: 0 | N39: 0 | O39: =AVERAGE(K39:N39) -> 0 | P39: 0 | Q39: 0 | R39: 0 | S39: 0 | T39: =AVERAGE(P39:S39) -> 0 | U39: 0 | V39: 0 | W39: 0 | X39: 0 | Y39: =AVERAGE(U39:X39) -> 0 | Z39: 0 | AA39: 0 | AB39: 0 | AC39: 0 | AD39: =AVERAGE(Z39:AC39) -> 0 | AE39: 0 | AF39: 0 | AG39: 0 | AH39: 0 | AI39: =AVERAGE(AE39:AH39) -> 0 | AJ39: 50 | AK39: 37.5 | AL39: 25 | AM39: 25 | AN39: =AVERAGE(AJ39:AM39) -> 34.375 | AO39: =SUM((O39>0)*1,(T39>0)*1,(Y39>0)*1,(AD39>0)*1,(AI39>0)*1,(AN39>0)*1) -> 1 | AQ39: 10 | AR39: 30
B40: 70 | F40: =sum(K40,P40,U40,Z40,AE40,AJ40) -> 0 | G40: =sum(L40,Q40,V40,AA40,AF40,AK40) -> 0 | H40: =sum(M40,R40,W40,AB40,AG40,AL40) -> 0 | I40: =sum(N40,S40,X40,AC40,AH40,AM40) -> 0 | J40: =AVERAGE(F40:I40) -> 0 | K40: 0 | L40: 0 | M40: 0 | N40: 0 | O40: =AVERAGE(K40:N40) -> 0 | P40: 0 | Q40: 0 | R40: 0 | S40: 0 | T40: =AVERAGE(P40:S40) -> 0 | U40: 0 | V40: 0 | W40: 0 | X40: 0 | Y40: =AVERAGE(U40:X40) -> 0 | Z40: 0 | AA40: 0 | AB40: 0 | AC40: 0 | AD40: =AVERAGE(Z40:AC40) -> 0 | AE40: 0 | AF40: 0 | AG40: 0 | AH40: 0 | AI40: =AVERAGE(AE40:AH40) -> 0 | AJ40: 0 | AK40: 0 | AL40: 0 | AM40: 0 | AN40: =AVERAGE(AJ40:AM40) -> 0 | AO40: =SUM((O40>0)*1,(T40>0)*1,(Y40>0)*1,(AD40>0)*1,(AI40>0)*1,(AN40>0)*1) -> 0 | AQ40: 0 | AR40: 30
B41: 80 | F41: =sum(K41,P41,U41,Z41,AE41,AJ41) -> 75 | G41: =sum(L41,Q41,V41,AA41,AF41,AK41) -> 75 | H41: =sum(M41,R41,W41,AB41,AG41,AL41) -> 75 | I41: =sum(N41,S41,X41,AC41,AH41,AM41) -> 75 | J41: =AVERAGE(F41:I41) -> 75 | K41: 0 | L41: 0 | M41: 0 | N41: 0 | O41: =AVERAGE(K41:N41) -> 0 | P41: 0 | Q41: 0 | R41: 0 | S41: 0 | T41: =AVERAGE(P41:S41) -> 0 | U41: 25 | V41: 25 | W41: 25 | X41: 25 | Y41: =AVERAGE(U41:X41) -> 25 | Z41: 0 | AA41: 0 | AB41: 0 | AC41: 0 | AD41: =AVERAGE(Z41:AC41) -> 0 | AE41: 0 | AF41: 0 | AG41: 0 | AH41: 0 | AI41: =AVERAGE(AE41:AH41) -> 0 | AJ41: 50 | AK41: 50 | AL41: 50 | AM41: 50 | AN41: =AVERAGE(AJ41:AM41) -> 50 | AO41: =SUM((O41>0)*1,(T41>0)*1,(Y41>0)*1,(AD41>0)*1,(AI41>0)*1,(AN41>0)*1) -> 2 | AQ41: 10 | AR41: 50
B42: 90 | F42: =sum(K42,P42,U42,Z42,AE42,AJ42) -> 100 | G42: =sum(L42,Q42,V42,AA42,AF42,AK42) -> 75 | H42: =sum(M42,R42,W42,AB42,AG42,AL42) -> 75 | I42: =sum(N42,S42,X42,AC42,AH42,AM42) -> 56.25 | J42: =AVERAGE(F42:I42) -> 76.5625 | K42: 25 | L42: 12.5 | M42: 12.5 | N42: 6.25 | O42: =AVERAGE(K42:N42) -> 14.0625 | P42: 0 | Q42: 0 | R42: 0 | S42: 0 | T42: =AVERAGE(P42:S42) -> 0 | U42: 25 | V42: 25 | W42: 25 | X42: 25 | Y42: =AVERAGE(U42:X42) -> 25 | Z42: 0 | AA42: 0 | AB42: 0 | AC42: 0 | AD42: =AVERAGE(Z42:AC42) -> 0 | AE42: 0 | AF42: 0 | AG42: 0 | AH42: 0 | AI42: =AVERAGE(AE42:AH42) -> 0 | AJ42: 50 | AK42: 37.5 | AL42: 37.5 | AM42: 25 | AN42: =AVERAGE(AJ42:AM42) -> 37.5 | AO42: =SUM((O42>0)*1,(T42>0)*1,(Y42>0)*1,(AD42>0)*1,(AI42>0)*1,(AN42>0)*1) -> 3 | AP42: 36 | AQ42: 15 | AR42: 30
...

Sheet Jepara - Kayu Apung
A1: Jepara
A2: Stasiun | B2: Pantai Kayu Apung | F2: Tanggal | K2: Catatan:
A3: Pengamat | B3: Dio, Reza, Humam, Agus | F3: Waktu
A5: Informasi umum: | D5: Cuaca | G5: Kecerahan | K5: Sungai | U5: Kedalaman
D6: Mangove | G6: Dermaga | U6: Aktivitas | V6: Pariwisata dan Memancing
A8: Transek | C8: Koordinat | E8: Substrat | F8: Nilai Penutupan Lamun | J8: Rata - Rata Penutupan Lamun (%) | K8: Nilai penutupan lamun per jenis | AO8: Kekayaan Spesies | AP8: Kerapatan Ea (m2) | AQ8: Penutupan | AT8: Kecerahan air | AU8: Catatan
A9: Line | B9: Meter | C9: Lat | D9: Long | F9: Kotak | L9: Ea | O9: Rata - Rata (%) | Q9: Th | T9: Rata - Rata (%) | V9: Cr | Y9: Rata - Rata (%) | Z9: Si | AD9: Rata-Rata (%) | AE9: Hu | AI9: Rata - Rata (%) | AJ9: Os | AN9: Rata - Rata (%) | AQ9: Makroalga | AR9: Epifit | AS9: Tipe
F10: 1 | G10: 2 | H10: 3 | I10: 4 | K10: 1 | L10: 2 | M10: 3 | N10: 4 | P10: 1 | Q10: 2 | R10: 3 | S10: 4 | U10: 1 | V10: 2 | W10: 3 | X10: 4 | Z10: 1 | AA10: 2 | AB10: 3 | AC10: 4 | AE10: 1 | AF10: 2 | AG10: 3 | AH10: 4 | AJ10: 1 | AK10: 2 | AL10: 3 | AM10: 4 | AR10: (%) | AS10: Substrat
A11: 1 | B11: 0 | C11: -6.549433° E, 110.654463° S | E11: 37.5 | F11: =sum(K11,P11,U11,Z11,AE11,AJ11) -> 50 | G11: =sum(L11,Q11,V11,AA11,AF11,AK11) -> 50 | H11: =sum(M11,R11,W11,AB11,AG11,AL11) -> 37.5 | I11: =sum(N11,S11,X11,AC11,AH11,AM11) -> 25 | J11: =AVERAGE(F11:I11) -> 40.625 | K11: 0 | L11: 0 | M11: 0 | N11: 0 | O11: =AVERAGE(K11:N11) -> 0 | P11: 0 | Q11: 0 | R11: 0 | S11: 0 | T11: =AVERAGE(P11:S11) -> 0 | U11: 0 | V11: 0 | W11: 0 | X11: 0 | Y11: =AVERAGE(U11:X11) -> 0 | Z11: 0 | AA11: 0 | AB11: 0 | AC11: 0 | AD11: =AVERAGE(Z11:AC11) -> 0 | AE11: 0 | AF11: 0 | AG11: 0 | AH11: 0 | AI11: =AVERAGE(AE11:AH11) -> 0 | AJ11: 50 | AK11: 50 | AL11: 37.5 | AM11: 25 | AN11: =AVERAGE(AJ11:AM11) -> 40.625 | AO11: =SUM((O11>0)*1,(T11>0)*1,(Y11>0)*1,(AD11>0)*1,(AI11>0)*1,(AN11>0)*1) -> 1 | AQ11: 10 | AR11: 70 | AS11: Rubble | AT11: Cerah
